Workbook

Sheet Dashboard
A2: Key inputs
B3: Fee | C3: Cost
A4: On Ramp
A5: Card payment | B5: 0 | C5: =B5*0.8 -> 0
A6: Bank transfer | B6: 0 | C6: =B6*0.25 -> 0
A7: Crypto-crypto swap | B7: 0.00875 | C7: 0
A8: Off Ramp
A9: Bank transfer | B9: 0.01 | C9: 0.002
A10: Interchange | B10: 0.002 | C10: 0.0005
A11: Membership Subscription | B11: 9.99
A12: ROI on Invested Treasury | B12: 0
A14: Invested Capital | B14: 12000000
A16: MVP Users | B16: 2000
A17: Conversion GBP to EUR | B17: 1.13
A22: Oly dashboard | B22: Q1 2023 | C22: Q2 2023 | D22: Q3 2023 | E22: Q4 2023 | F22: Y 2023
A24: Revenue Streams
A25: Card Sales | B25: =SUM('Revenues'!C9:E9) -> 59626.14 | C25: =SUM('Revenues'!F9:H9) -> 246301.44 | D25: =SUM('Revenues'!I9:K9) -> 799580.04 | E25: =SUM('Revenues'!L9:N9) -> 2593012.4 | F25: =SUM(Table9[[#This Row],[Q1 2023]:[Q4 2023]]) -> 3698520
A26: On Ramp | B26: =SUM('Revenues'!C21:E21) -> 0 | C26: =SUM('Revenues'!F21:H21) -> 0 | D26: =SUM('Revenues'!I21:K21) -> 0 | E26: =SUM('Revenues'!L21:N21) -> 0 | F26: =SUM(Table9[[#This Row],[Q1 2023]:[Q4 2023]]) -> 0
A27: Swap Crypto to Crypto | B27: =SUM('Revenues'!C29:E29) -> 15933.575 | C27: =SUM('Revenues'!F29:H29) -> 51386.159 | D27: =SUM('Revenues'!I29:K29) -> 166835.9 | E27: =SUM('Revenues'!L29:N29) -> 541434.09 | F27: =SUM(Table9[[#This Row],[Q1 2023]:[Q4 2023]]) -> 775589.73
A28: Off Ramp | B28: =SUM('Revenues'!C39:E39) -> 26222.112 | C28: =SUM('Revenues'!F39:H39) -> 84566.936 | D28: =SUM('Revenues'!I39:K39) -> 274564.23 | E28: =SUM('Revenues'!L39:N39) -> 891045.82 | F28: =SUM(Table9[[#This Row],[Q1 2023]:[Q4 2023]]) -> 1276399.1
A29: Transfer (Crypto to Crypto) | B29: =SUM('Revenues'!C55:E55) -> 0 | C29: =SUM('Revenues'!F55:H55) -> 0 | D29: =SUM('Revenues'!I55:K55) -> 0 | E29: =SUM('Revenues'!L55:N55) -> 0 | F29: =SUM(Table9[[#This Row],[Q1 2023]:[Q4 2023]]) -> 0
A30: Membership Subscription | B30: =SUM('Revenues'!C62:E62) -> 4547.8975 | C30: =SUM('Revenues'!F62:H62) -> 14667.078 | D30: =SUM('Revenues'!I62:K62) -> 47619.734 | E30: =SUM('Revenues'!L62:N62) -> 154540.76 | F30: =SUM(Table9[[#This Row],[Q1 2023]:[Q4 2023]]) -> 221375.47
A31: Treasury Management | B31: =SUM('Revenues'!C75:E75) -> 0 | C31: =SUM('Revenues'!F75:H75) -> 0 | D31: =SUM('Revenues'!I75:K75) -> 0 | E31: =SUM('Revenues'!L75:N75) -> 0 | F31: =SUM(Table9[[#This Row],[Q1 2023]:[Q4 2023]]) -> 0
A32: Total Revenue | B32: =SUM(B25:B31) -> 106329.72 | C32: =SUM(C25:C31) -> 396921.61 | D32: =SUM(D25:D31) -> 1288599.9 | E32: =SUM(E25:E31) -> 4180033 | F32: =SUM(Table9[[#This Row],[Q1 2023]:[Q4 2023]]) -> 5971884.3
A34: Direct Costs
A35: Card Sales | B35: =-SUM('Direct Costs'!C11:E11) -> -54184.644 | C35: =-SUM('Direct Costs'!F11:H11) -> -121761.02 | D35: =-SUM('Direct Costs'!I11:K11) -> -395278.58 | E35: =-SUM('Direct Costs'!L11:N11) -> -1281875.7 | F35: =SUM(Table9[[#This Row],[Q1 2023]:[Q4 2023]]) -> -1853100
A36: On Ramp | B36: =-SUM('Direct Costs'!C23:E23) -> 0 | C36: =-SUM('Direct Costs'!F23:H23) -> 0 | D36: =-SUM('Direct Costs'!I23:K23) -> 0 | E36: =-SUM('Direct Costs'!L23:N23) -> 0 | F36: =SUM(Table9[[#This Row],[Q1 2023]:[Q4 2023]]) -> 0
A37: Swap Crypto to Crypto | B37: =-SUM('Direct Costs'!C31:E31) -> 0 | C37: =-SUM('Direct Costs'!F31:H31) -> 0 | D37: =-SUM('Direct Costs'!I31:K31) -> 0 | E37: =-SUM('Direct Costs'!L31:N31) -> 0 | F37: =SUM(Table9[[#This Row],[Q1 2023]:[Q4 2023]]) -> 0
A38: Off Ramp | B38: =-SUM('Direct Costs'!C39:E39) -> -1121.76 | C38: =-SUM('Direct Costs'!F39:H39) -> -3642.6 | D38: =-SUM('Direct Costs'!I39:K39) -> -11826.48 | E38: =-SUM('Direct Costs'!L39:N39) -> -38381.04 | F38: =SUM(Table9[[#This Row],[Q1 2023]:[Q4 2023]]) -> -54971.88
A39: Transfer (Crypto to Crypto) | B39: =-SUM('Direct Costs'!C55:E55) -> 0 | C39: =-SUM('Direct Costs'!F55:H55) -> 0 | D39: =-SUM('Direct Costs'!I55:K55) -> 0 | E39: =SUM('Direct Costs'!L55:N55) -> 0 | F39: =SUM(Table9[[#This Row],[Q1 2023]:[Q4 2023]]) -> 0
A40: Membership Subscription | B40: =-SUM('Direct Costs'!C64:E64) -> -3417.147 | C40: =-SUM('Direct Costs'!F64:H64) -> -9373.297 | D40: =-SUM('Direct Costs'!I64:K64) -> -32092.127 | E40: =-SUM('Direct Costs'!L64:N64) -> -102454.76 | F40: =SUM(Table9[[#This Row],[Q1 2023]:[Q4 2023]]) -> -147337.33
A41: Treasury Management | B41: =-SUM('Direct Costs'!C77:E77) -> 0 | C41: =-SUM('Direct Costs'!F77:H77) -> 0 | D41: =-SUM('Direct Costs'!I77:K77) -> 0 | E41: =-SUM('Direct Costs'!L77:N77) -> 0 | F41: =SUM(Table9[[#This Row],[Q1 2023]:[Q4 2023]]) -> 0
A42: Total Direct Costs | B42: =SUM(B35:B41) -> -58723.551 | C42: =SUM(C35:C41) -> -134776.92 | D42: =SUM(D35:D41) -> -439197.19 | E42: =SUM(E35:E41) -> -1422711.5 | F42: =SUM(Table9[[#This Row],[Q1 2023]:[Q4 2023]]) -> -2055409.2
A44: Gross Profit | B44: =B32+B42 -> 47606.174 | C44: =C32+C42 -> 262144.69 | D44: =D32+D42 -> 849402.72 | E44: =E32+E42 -> 2757321.5 | F44: =F32+F42 -> 3916475.1
A46: Operating Expenditure
A47: Payroll | B47: -665850.14 | C47: -665850.14 | D47: -682241.39 | E47: -682241.39 | F47: -2696183.1
A48: Other Operating Expenses | B48: -600304.11 | C48: -160304.11 | D48: -163582.36 | E48: -163582.36 | F48: -1087773
A49: Total Operating Expenditure | B49: -1266154.3 | C49: -826154.26 | D49: -845823.76 | E49: -845823.76 | F49: -3783956
A51: EBITDA | B51: -1218548.1 | C51: -564009.57 | D51: 3578.9578 | E51: 1911497.7 | F51: 132519.04
A53: Capital Expenditure
...

Sheet Unit Economics
A2: Unit Economics | B2: Oly | C2: Oly
A3: Customer Lifetime = 20 months
A5: Lifetime Value
A6: Card Sales | B6: ='Fee Structure'!B2 -> 24.99 | C6: =B6-B17 -> 7.64
A7: On Ramp | B7: ='Revenues'!D20*20 -> 0 | C7: =B7-B18 -> 0
A8: Swap Crypto to Crypto | B8: ='Revenues'!D28*20 -> 35 | C8: =B8-B19 -> 35
A9: Off Ramp (Card Payment) | B9: ='Revenues'!D38*20 -> 57.6 | C9: =B9-B20 -> 55.2
A10: Off Ramp (Bank Transfer) | B10: ='Revenues'!D46*20 -> 0 | C10: =B10-B21 -> 0
A11: Transfer (Crypto to Crypto) | B11: ='Revenues'!D54*20 -> 0 | C11: =B11-B22 -> 0
A12: Membership Subscription | B12: ='Revenues'!D61*'Revenues'!D58 -> 0.4995 | C12: =B12-B23 -> -0.3805
A13: Treasury Management | B13: =SUM(B37:U37) -> 105 | C13: =B13-B24 -> 91.875
A14: Total LTV | B14: =SUM(B6:B13) -> 223.0895 | C14: =SUM(C6:C13) -> 189.3345
A16: Customer Acquisition Costs
A17: Card Sales | B17: =17.35 -> 17.35 | C17: =17.35 -> 17.35
A18: On Ramp | B18: ='Direct Costs'!D22*20 -> 0 | C18: ='[1]Direct Costs'!G21*20 -> 54.012
A19: Swap Crypto to Crypto | B19: ='Direct Costs'!D30*20 -> 0 | C19: ='[1]Direct Costs'!G29*20 -> 0
A20: Off Ramp (Card Payment) | B20: ='Direct Costs'!D38*20 -> 2.4 | C20: ='[1]Direct Costs'!G37*20 -> 2
A21: Off Ramp (Bank Transfer) | B21: ='Direct Costs'!D46*20 -> 0 | C21: ='[1]Direct Costs'!G45*20 -> 0.008
A22: Transfer (Crypto to Crypto) | B22: ='Direct Costs'!D54*20 -> 0 | C22: ='[1]Direct Costs'!G53*20 -> 0
A23: Membership Subscription | B23: =(10+(0.38*20))*5% -> 0.88 | C23: =(10+(0.38*20))*5% -> 0.88
A24: Treasury Management | B24: =SUM(B39:U39) -> 13.125 | C24: =SUM(E39:X39) -> 9.5625
A25: Selling & Marketing
A26: Total CAC | B26: =SUM(B17:B24) -> 33.755 | C26: =SUM(C25) -> 0
A28: LTV/CAC | B28: =B14/B26 -> 6.6090801 | C28: =C14 -> 189.3345
A33: On Ramped | B33: 600 | C33: 600 | D33: 600 | E33: 600 | F33: 600 | G33: 600 | H33: 600 | I33: 600 | J33: 600 | K33: 600 | L33: 600 | M33: 600 | N33: 600 | O33: 600 | P33: 600 | Q33: 600 | R33: 600 | S33: 600 | T33: 600 | U33: 600
A34: Amount Invested | B34: =B33/2 -> 300 | C34: =C33/2 -> 300 | D34: =D33/2 -> 300 | E34: =E33/2 -> 300 | F34: =F33/2 -> 300 | G34: =G33/2 -> 300 | H34: =H33/2 -> 300 | I34: =I33/2 -> 300 | ... U34: =U33/2 -> 300
A35: Months Invested | B35: 20 | C35: 19 | D35: 18 | E35: 17 | F35: 16 | G35: 15 | H35: 14 | I35: 13 | J35: 12 | K35: 11 | L35: 10 | M35: 9 | N35: 8 | O35: 7 | P35: 6 | Q35: 5 | R35: 4 | S35: 3 | T35: 2 | U35: 1
A36: Adjusted Return | B36: =2%*(B35/12) -> 0.033333333 | C36: =2%*(C35/12) -> 0.031666667 | D36: =2%*(D35/12) -> 0.03 | E36: =2%*(E35/12) -> 0.028333333 | F36: =2%*(F35/12) -> 0.026666667 | G36: =2%*(G35/12) -> 0.025 | H36: =2%*(H35/12) -> 0.023333333 | I36: =2%*(I35/12) -> 0.021666667 | ... U36: =2%*(U35/12) -> 0.0016666667
B37: =B34*B36 -> 10 | C37: =C34*C36 -> 9.5 | D37: =D34*D36 -> 9 | E37: =E34*E36 -> 8.5 | F37: =F34*F36 -> 8 | G37: =G34*G36 -> 7.5 | H37: =H34*H36 -> 7 | I37: =I34*I36 -> 6.5 | ... U37: =U34*U36 -> 0.5
A38: Cost | B38: =0.5%*(B37/12) -> 0.0041666667 | C38: =0.5%*(C37/12) -> 0.0039583333 | D38: =0.5%*(D37/12) -> 0.00375 | E38: =0.5%*(E37/12) -> 0.0035416667 | F38: =0.5%*(F37/12) -> 0.0033333333 | G38: =0.5%*(G37/12) -> 0.003125 | H38: =0.5%*(H37/12) -> 0.0029166667 | I38: =0.5%*(I37/12) -> 0.0027083333 | ... U38: =0.5%*(U37/12) -> 0.00020833333
B39: =B34*B38 -> 1.25 | C39: =C34*C38 -> 1.1875 | D39: =D34*D38 -> 1.125 | E39: =E34*E38 -> 1.0625 | F39: =F34*F38 -> 1 | G39: =G34*G38 -> 0.9375 | H39: =H34*H38 -> 0.875 | I39: =I34*I38 -> 0.8125 | ... U39: =U34*U38 -> 0.0625

Sheet IRR Analysis
A1: IRR Returns Analysis | O1: Notes
A3: Returns in 5 years
A4: Entry Multiple (2022 GP) | C4: 5.5555556
A5: GP 2022 (annualised September) | C5: 360
A6: Entry valuation | C6: =C5*C4 -> 2000
A7: EXIT Multiple (5 years) | C7: 3 | D7: =C4*C5 -> 2000
A8: GP in 2027F | C8: 2867
A9: Enterprise Value (EXIT) €m | C9: =+C7*C8 -> 8601
A10: Less: Net Debt | C10: 0
A11: Equity Value (EXIT) €m | C11: =+C9-C10 -> 8601
C13: 44561 | D13: =+C13+366 -> 44927 | E13: =+D13+365 -> 45292 | F13: =+E13+365 -> 45657 | G13: =+F13+365 -> 46022 | H13: =+G13+366 -> 46388 | I13: =+H13+1 -> 46389 | J13: =+I13+1 -> 46390 | K13: =+J13+1 -> 46391 | L13: =+K13+1 -> 46392 | M13: =+L13+1 -> 46393
C14: =+'[2]Balance Sheet'!F4 -> 2021 | D14: =+'[2]Balance Sheet'!H4 -> 2022 | E14: =+'[2]Balance Sheet'!I4 -> 2023 | F14: =+'[2]Balance Sheet'!J4 -> 2024 | G14: =+'[2]Balance Sheet'!K4 -> 2025 | H14: =+'[2]Balance Sheet'!L4 -> 2026 | I14: 2027 | J14: =+'[2]Balance Sheet'!#REF! -> #REF! | K14: =+'[2]Balance Sheet'!#REF! -> #REF! | L14: =+'[2]Balance Sheet'!#REF! -> #REF! | M14: =+'[2]Balance Sheet'!#REF! -> #REF!
A16: Free Cash Flow to Equity
A17: Equity Investment | D17: =-D7 -> -2000
A18: Equity inflow at the time of sale | H18: 0 | I18: =C9 -> 8601
A19: Total Cashflows | C19: 0 | D19: =+D16+D17+D18 -> -2000 | E19: =+E16+E17+E18 -> 0 | F19: =+F16+F17+F18 -> 0 | G19: =+G16+G17+G18 -> 0 | H19: =+H16+H17+H18 -> 0 | I19: =+I16+I17+I18 -> 8601
A21: IRR | C21: =+XIRR(D19:I19,D13:I13) -> 0.43933894
A22: MOIC | C22: =I19/-D19 -> 4.3005
D24: 1 | E24: =+D24+1 -> 2 | F24: =+E24+1 -> 3 | G24: =+F24+1 -> 4 | H24: =+G24+1 -> 5
C25: =C14 -> 2021 | D25: =D14 -> 2022 | E25: =E14 -> 2023 | F25: =F14 -> 2024 | G25: =G14 -> 2025 | H25: =H14 -> 2026 | I25: =I14 -> 2027 | J25: =J14 -> #REF! | ... M25: =M14 -> #REF!
A27: Total Cashflows | H27: =+H19 -> 0
A29: Factor | D29: =1/((1+$C$34)^D24) -> 0.69476339 | E29: =1/((1+$C$34)^E24) -> 0.48269617 | F29: =1/((1+$C$34)^F24) -> 0.33535962 | G29: =1/((1+$C$34)^G24) -> 0.23299559 | H29: =1/((1+$C$34)^H24) -> 0.16187681
A31: Discounted FCF | D31: =+D27*D29 -> 0 | E31: =+E27*E29 -> 0 | F31: =+F27*F29 -> 0 | G31: =+G27*G29 -> 0 | H31: =+H27*H29 -> 0 | I31: =+I27*I29 -> 0 | J31: =+J27*J29 -> 0 | K31: =+K27*K29 -> 0 | ... M31: =+M27*M29 -> 0
A34: IRR | C34: =C21 -> 0.43933894
A36: Entry Equity Value | C36: =+SUM(D31:H31) -> 0
A37: Net Debt | C37: =C10 -> 0
A38: Enterprise value | C38: =C36+C37 -> 0
A39: EV/EBITDA FY+1 | C39: =+C38/'[2]DCF (5YR)'!G31 -> 0
C42: 5 year Exit scenario (Exit Multiple = 20.5x FY+1 EBITDA)
C43: 0.05 | D43: =+C43+0.01 -> 0.06 | E43: =+D43+0.01 -> 0.07 | F43: =+E43+0.01 -> 0.08 | G43: =+F43+0.01 -> 0.09 | H43: =+G43+0.01 -> 0.1 | I43: =+H43+0.01 -> 0.11 | J43: 0.2157118 | K43: =+J43+0.01 -> 0.2257118 | L43: =+K43+0.01 -> 0.2357118 | M43: 0.25
A44: Entry Price | B44: =+C38 -> 0 | C44: 0 | D44: 0 | E44: 0 | F44: 0 | G44: 0 | H44: 0 | I44: 0 | J44: 0 | K44: 0 | L44: 0 | M44: 0

Sheet Valuation - DCF
B1: 5-Year DCF Analysis
A2: `
F3: Projections
F4: 2022 | G4: 2023 | H4: 2024
B6: Assumptions | J6: Exit Multiple
B7: Debt | D7: 0 | J7: Sum of PV of Unlevered FCF | P7: =SUM(F50:H50) -> 26525.993
B8: Shares | D8: 0
B9: Tax Rate | D9: 0.19 | J9: EV/Revenue Exit Multiple | P9: =D12 -> 20
B10: WACC | D10: 0.15 | J10: Terminal Value | P10: =#REF! -> #REF!
B11: Exit Revenue Multiple (forward) 2023 | D11: 20
B12: Exit Revenue Multiple (forward) 2024 | D12: 20 | J12: PV of Terminal Value | P12: =#REF! -> #REF!
B13: Perpetuity Growth Rate | D13: 0.03
B14: CapEx | D14: 0.001 | J14: Implied Enterprise Value | P14: =#REF! -> #REF!
B15: NWC | D15: -0.015 | J15: 2023 Revenue | P15: =+F31 -> 0
B16: D&A (as % of Revenue) | D16: 0.01 | J16: Implied Rev Multiple | P16: =+P14/P15 -> #REF!
B18: Mid-year Adjustment | D18: 1 | J18: 2024 EBITDA | P18: =+G31 -> 132519.04
J19: Implied Rev Multiple | P19: =P14/P18 -> #REF!
B20: DCF (USD)
B21: Net Revenue | G21: =Dashboard!F32 -> 5971884.3 | L21: Exit Multiple - EV / EBITDA (x)
B22: % Growth | F22: =IFERROR(F21/#REF!-1,0) -> 0 | G22: =IFERROR(G21/F21-1,0) -> 0 | H22: =IFERROR(H21/G21-1,0) -> -1 | K22: =#REF! -> #REF! | L22: =M22-1 -> 47.776558 | M22: =N22-1 -> 48.776558 | N22: 49.776558 | O22: =N22+1 -> 50.776558 | P22: =O22+1 -> 51.776558
J23: WACC (%) | K23: 0.15 | L23: 692.09042 | M23: 705.42796 | N23: 718.76549 | O23: 732.10303 | P23: 745.44057
B24: Gross Profit | G24: =Dashboard!F44 -> 3916475.1 | K24: 0.175 | L24: 623.85999 | M24: 635.83775 | N24: 647.81551 | O24: 659.79326 | P24: 671.77102
B25: % Growth | F25: =IFERROR(F24/#REF!-1,0) -> 0 | G25: =IFERROR(G24/F24-1,0) -> 0 | H25: =IFERROR(H24/G24-1,0) -> -1 | K25: 0.15 | L25: 692.09042 | M25: 705.42796 | N25: 718.76549 | O25: 732.10303 | P25: 745.44057
B26: % Margin | F26: =IFERROR(F24/F21,0) -> 0 | G26: =IFERROR(G24/G21,0) -> 0.65581898 | H26: =IFERROR(H24/H21,0) -> 0 | K26: 0.25 | L26: 463.45648 | M26: 472.247 | N26: 481.03753 | O26: 489.82805 | P26: 498.61857
K27: 0.3 | L27: 384.34452 | M27: 391.56969 | N27: 398.79486 | O27: 406.02003 | P27: 413.2452
B28: OPEX | G28: =Dashboard!F49 -> -3783956
B29: % of GP | F29: =-F28/F24 -> #DIV/0! | G29: =-G28/G24 -> 0.9661637 | H29: =-H28/H24 -> #DIV/0!
L30: Perpetuity Growth Rate (%)
B31: EBITDA | G31: =G24+G28 -> 132519.04 | K31: =+#REF! -> #REF! | L31: 0.03 | M31: 0.04 | N31: 0.05 | O31: 0.06 | P31: 0.07
B32: % Growth | F32: =IFERROR((-#REF!+F31)/-#REF!,0) -> 0 | G32: =IFERROR(G31/F31-1,0) -> 0 | H32: =IFERROR(H31/G31-1,0) -> -1 | J32: WACC (%) | K32: =K33-2.5% -> 0.1 | L32: 172.49474 | M32: 192.07866 | N32: 219.49615 | O32: 260.62238 | P32: 329.1661
B33: % Margin | F33: =+IFERROR(F31/F21,0) -> 0 | G33: =+IFERROR(G31/G21,0) -> 0.022190491 | H33: =+IFERROR(H31/H21,0) -> 0 | K33: =K34-2.5% -> 0.125 | L33: 123.22929 | M33: 131.55014 | N33: 142.08989 | O33: 155.87263 | P33: 174.66729
K34: 0.15 | L34: 96.017968 | M34: 100.19462 | N34: 105.20661 | O34: 111.33237 | P34: 118.98957
B35: (-) D&A | F35: =-$D$16*F21 -> 0 | G35: =-$D$16*G21 -> -59718.843 | H35: =-$D$16*H21 -> 0 | K35: =K34+2.5% -> 0.175 | L35: 79.06863 | M35: 81.389445 | N35: 84.08159 | O35: 87.241935 | P35: 91.00425
K36: =K35+2.5% -> 0.2 | L36: 67.617731 | M36: 68.999651 | N36: 70.565828 | O36: 72.355743 | P36: 74.421031
B37: Operating Income | F37: =+F31+F35 -> 0 | G37: =+G31+G35 -> 72800.201 | H37: =+H31+H35 -> 0
B39: (-) Tax | F39: =+F37*-$D$9 -> 0 | G39: =+G37*-$D$9 -> -13832.038 | H39: =+H37*-$D$9 -> 0
B41: NOPAT | F41: =SUM(F37:F39) -> 0 | G41: =SUM(G37:G39) -> 58968.163 | H41: =SUM(H37:H39) -> 0
B42: (+) D&A | F42: =+-F35 -> 0 | G42: =+-G35 -> 59718.843 | H42: =+-H35 -> 0
B43: (-) CapEx | F43: =F21*$D$14 -> 0 | G43: =G21*$D$14 -> 5971.8843 | H43: =H21*$D$14 -> 0
B44: (+/-) NWC | F44: =F21*$D$15 -> 0 | G44: =G21*$D$15 -> -89578.264 | H44: =H21*$D$15 -> 0
...

Sheet Valuation - Comps
B1: Relative Valuation
B4: Key Financials | G4: =TEXT("Valuation Forecasts (EURm)",0)&" - "&[2]Assumptions!C5 -> Valuation Forecasts (EURm) - Management Case
B6: Forecasts | G6: Reference Year: 202EE
B7: USD | C7: 2022 | D7: =C7+1 -> 2023 | E7: =D7+1 -> 2024 | G7: Valuation Multiple | H7: Metric | I7: Multiple1 | J7: Discount | K7: Multiple2 | L7: EV
B8: Revenue | C8: ='Valuation - DCF'!F21 -> 0 | D8: ='Valuation - DCF'!G21 -> 5971884.3 | E8: ='Valuation - DCF'!H21 -> 0 | G8: EV/Sales | H8: =+D8 -> 5971884.3 | I8: =+H21 -> 100 | J8: 0 | K8: =I8*(1-J8) -> 100 | L8: =IF(PRODUCT(H8,K8)<0,"n.m.",H8*K8) -> 5.9718843e+08
B9: Gross Profit | C9: ='Valuation - DCF'!F24 -> 0 | D9: ='Valuation - DCF'!G24 -> 3916475.1 | E9: ='Valuation - DCF'!H24 -> 0 | G9: EV/Gross Profit | H9: =+D9 -> 3916475.1 | I9: =+H22 -> 10.985315 | J9: 0 | K9: =I9*(1-J9) -> 10.985315 | L9: =IF(PRODUCT(H9,K9)<0,"n.m.",H9*K9) -> 43023712
B10: EBITDA | C10: ='Valuation - DCF'!F31 -> 0 | D10: ='Valuation - DCF'!G31 -> 132519.04 | E10: ='Valuation - DCF'!H31 -> 0 | G10: EV/EBITDA | H10: =+D10 -> 132519.04 | I10: =+H23 -> 20.542607 | J10: 0 | K10: =I10*(1-J10) -> 20.542607 | L10: =IF(PRODUCT(H10,K10)<0,"n.m.",H10*K10) -> 2722286.7
G12: Reference Year: 2024E
B13: YoY Growth (%) | C13: 2022 | D13: =C13+1 -> 2023 | E13: =D13+1 -> 2024 | G13: Valuation Multiple | H13: Metric | I13: Multiple1 | J13: Discount | K13: Multiple2 | L13: EV
B14: Revenue | C14: - | D14: =D8/C8-1 -> #DIV/0! | E14: =E8/D8-1 -> -1 | G14: EV/Sales | H14: =E8 -> 0 | I14: =+J21 -> 3.9804369 | J14: 0 | K14: =I14*(1-J14) -> 3.9804369 | L14: =IF(PRODUCT(H14,K14)<0,"n.m.",H14*K14) -> 0
B15: Gross Profit | C15: - | D15: =D9/C9-1 -> #DIV/0! | E15: =E9/D9-1 -> -1 | G15: EV/Gross Profit | H15: =E9 -> 0 | I15: =+J22 -> 7.7888592 | J15: 0 | K15: =I15*(1-J15) -> 7.7888592 | L15: =IF(PRODUCT(H15,K15)<0,"n.m.",H15*K15) -> 0
B16: EBITDA | C16: - | D16: =D10/C10-1 -> #DIV/0! | E16: =E10/D10-1 -> -1 | G16: EV/EBITDA | H16: =E10 -> 0 | I16: =+J23 -> 14.029556 | J16: 0 | K16: =I16*(1-J16) -> 14.029556 | L16: =IF(PRODUCT(H16,K16)<0,"n.m.",H16*K16) -> 0
G18: Market Multiples
H19: 2022E | J19: 2023E
B20: Notes: | G20: Valuation Multiple | H20: Average | I20: Median | J20: Average | K20: Median
B21: Multiple1 refers to the AVERAGE trading multiple of comparable companies. | G21: EV/Sales | H21: =AVERAGE(H27) -> 100 | I21: =MEDIAN(H27) -> 100 | J21: ='[2]Trading Comps'!H232 -> 3.9804369 | K21: ='[2]Trading Comps'!H233 -> 2.7182883
B22: Multiple2 refers to the adjusted multiple applied after discounts / premiums | G22: EV/Gross Profit | H22: ='[2]Trading Comps'!I232 -> 10.985315 | I22: ='[2]Trading Comps'!I233 -> 7.6827423 | J22: ='[2]Trading Comps'!J232 -> 7.7888592 | K22: ='[2]Trading Comps'!J233 -> 6.0947771
G23: EV/EBITDA | H23: ='[2]Trading Comps'!K232 -> 20.542607 | I23: ='[2]Trading Comps'!K233 -> 15.049253 | J23: ='[2]Trading Comps'!L232 -> 14.029556 | K23: ='[2]Trading Comps'!L233 -> 11.506256
H25: 2022E | I25: 2023E
G26: Valuation Multiple | H26: Tangem
G27: EV/Sales | H27: 100
G28: EV/Gross Profit
G29: EV/EBITDA
A54: x
A62: x

Sheet Valuation - VC method
A1: LTV | D1: Assumption
A2: Annual churn rate
A3: Set up rev
A4: Transaction rev
A5: Av volume pcm
A6: Other rev
A8: Total
A10: CAC
A15: Total | E15: EBITDA MARGIN SENSITIVITY TABLES ON EBITDA - what is ebitda margin for this biz
A17: Gross Profit
A18: Cardholders
A19: 100000 | B19: =($B$8-$B$15)*A19 -> 0
A20: 150000 | B20: =($B$8-$B$15)*A20 -> 0
A21: 500000 | B21: =($B$8-$B$15)*A21 -> 0
A22: 1000000 | B22: =($B$8-$B$15)*A22 -> 0
A23: 5000000 | B23: =($B$8-$B$15)*A23 -> 0
A24: 25000000 | B24: =($B$8-$B$15)*A24 -> 0

Sheet Assumptions >>>
A1: Assumptions >>>

Sheet Fee Structure
A1: Particulars | B1: Fee | C1: Reasoning | D1: Explanation
A2: Card Sales | B2: 24.99 | C2: We are targeting crypto natives firstly who have been paying 100s of dollars for good hardware wallets like ledger. Other hardware wallets such as Tangem sells their cards at $60 for a 3 card pack. Therefore, we believe this is a feasible price to sell this card to our audience | D2: Charge for selling the visa card to the user along with no backup
A3: On Ramp (Card Payment) | B3: =Dashboard!B5 -> 0 | C3: To cover high cost involved in bear scenario considering acquiring fee, issuing fee, scheme fee These are gross fees and by using saltpay acquiring and other services, we can bring it down to 0.5% + 20 bps as monerium is not acquired | D3: Charge for minting EURm by card payment
A4: On Ramp | B4: =Dashboard!$B$6 -> 0 | C4: Onramping only through bank transfer. No fees for onramping, only charge for off-ramping to increase liquidity of the stablecoin. We have a partnership with Monerium that enables us to do so. | D4: Charge for minting EURm by bank transfer
A5: Swap Crypto to Crypto | B5: =Dashboard!$B$7 -> 0.00875 | C5: This is based on competitor analysis. The biggest player (Metamask) has 0.875% fee on in app swaps. This is the same function, however at a lower fee. A 2021 study claimed that MetaMask was generating anywhere from $85,000 to $220,000 each day from these fees alone, with an estimated revenue of $100 million in 2021. | D5: Charge for swapping between various tokens on the wallet through cowswap
A6: Card Payment - Interchange | B6: =Dashboard!$B$10 -> 0.002 | C6: Interchange for VISA consumer debit is fixed at 0.2% in UK and EEA | D6: Charged to merchant as issuer of VISA consumer debit card
A7: Off Ramp (Bank Transfer) | B7: =Dashboard!$B$9 -> 0.01 | C7: Currently the closest hardware wallets competitors are Ledger, BitPay, and Wirex amongst others. While ledger has 2% fees as it is semi-self-custodial, others don’t reveal a fee but give a higher exchange rate for the off ramp. Tether issues USDT charges 0.1% on a minimum of 100,000 USD deposit/withdrawal. Circle charges between 0.2-0.3%, however only institutional investors qualify. Considering 0% fee on onramping, we believe 1% makes sense. | D7: Charge for transferring EURm to EUR to any bank account
A8: Transfer (Crypto to Crypto) | B8: 0 | C8: This is essentially peer to peer crypto transfers between wallets. Ledger has imposed a 0.4% fee on it, however most wallets do not impose a fee here as it is supposed to be an open system. | D8: Charge for transferring crypto directly out of the wallet (capped at $5)
A9: Membership Subscription | B9: =Dashboard!$B$11 -> 9.99 | C9: Based on avoidance of canibalisation of revenue lost due to discounts and cost of metal card | D9: Monthly charge per user for premium features and discount on fees
A10: Members as a % of users | B10: 0.05 | C10: In line with Monzo users, of which 8-9% are users paying for membership of various tiers
A11: ROI on Invested Treasury | B11: =Dashboard!$B$12 -> 0 | C11: This is considering Monerium acquisition is completed. Whenever monerium on ramps money, it holds fiat and mints EURm, which is a stablecoin pegged to EUR. It promises that any 1 EURm can be redeemed for 1 EUR, hence its essentially customers money indirectly. Monerium is in contact with state street to manage their money. As per industry standard, we need to maintain majority funds in cash and other in low risk low yield assets like government treasury bonds. Monerium team had informed that it is possible to get 2% return. | D11: ROI earned on customer funds invested in low-yield low-risk assets

Sheet Cost Structure
A1: Particulars | B1: Fee | C1: Reasoning | D1: Explanation
A2: On Ramp (Bank Transfer) | B2: =Dashboard!$C$6 -> 0 | C2: Monerium charging us 20 bps in bear scenario | D2: Cost of minting EURm by bank transfer
A3: Swap Crypto to Crypto | B3: =Dashboard!$C$7 -> 0 | C3: SEPA Transfer costs which are negligible | D3: Cost for swapping between various tokens on the wallet through cowswap
A4: Off Ramp (Card Payment - User) | B4: =Dashboard!$C$10 -> 0.0005 | C4: Cost to issue and process the cards with paymentology | D4: Cost for spending with EURm at any VISA merchant - Paymentology Cost
A5: Off Ramp (Bank Transfer) | B5: =Dashboard!$C$9 -> 0.002 | C5: No cost to off ramp with bank transfer | D5: Cost for transferring EURm to EUR to any bank account
A6: Transfer (Crypto to Crypto) | B6: 0 | C6: No cost to transfer crypto to crypto | D6: Cost for transferring crypto directly out of the wallet
A7: Membership Subscription | D7: Monthly charge per user for premium features and discount on fees
A8: Discount on fees for members | B8: 0.1 | C8: Idea behind membership, giving discounts to members on fees they incur while using Oly just like Revolut gives discount on trading fees for crypto, stocks and commodities. | D8: Fees discount given to members as a result of subscription
A9: Loss of revenue from fees | B9: =('Revenues'!$C$20+'Revenues'!$C$28+'Revenues'!$C$38+'Revenues'!$C$46+'Revenues'!$C$54)*B8 -> 0.463 | D9: Fees lost due to discount given to users
A10: Additional Cost of Metal Card | B10: 10 | D10: Additional costs of producing a metal card for members
A11: Cost of Investments of Treasury | B11: 0 | C11: As monerium is not acquired in bear scenario, we do not manage treasury | D11: Costs incurred for investments of treasury
A12: Card Sales
A13: Production Cost | B13: =(1.13+0.33)*2.4+1.65 -> 5.154 | C13: As per numbers from Tangem | D13: Cost to produce the average Tangem pack
A14: Packaging Cost | B14: 2.2 | C14: As per numbers from Tangem | D14: Cost to package the card
A15: Logistics Cost | B15: 5 | C15: As per numbers from Tangem | D15: Cost to deliver the card to the consumer
A16: Sales bonus and commissions | B16: 0.078624132 | C16: As per numbers from Tangem | D16: Average sales bonus commission in 2022 (% from revenue)

Sheet Oly Business >>>
A1: Oly Business >>>

Sheet Revenues
A1: Particulars | B1: Assumption | C1: Jan-23 | D1: Feb-23 | E1: Mar-23 | F1: Apr-23 | G1: May-23 | H1: Jun-23 | I1: Jul-23 | J1: Aug-23 | K1: Sep-23 | L1: Oct-23 | M1: Nov-23 | N1: Dec-23
A2: Number of Users | B2: Growing at a rate of 48.07% to reach 150,000 users by year end | C2: 2000 | D2: =ROUNDUP((C2*1.4807),0) -> 2962 | E2: =ROUNDUP((D2*1.4807),0) -> 4386 | F2: =ROUNDUP((E2*1.4807),0) -> 6495 | G2: =ROUNDUP((F2*1.4807),0) -> 9618 | H2: =ROUNDUP((G2*1.4807),0) -> 14242 | I2: =ROUNDUP((H2*1.4807),0) -> 21089 | J2: =ROUNDUP((I2*1.4807),0) -> 31227 | K2: =ROUNDUP((J2*1.4807),0) -> 46238 | ... M2: =ROUNDUP((L2*1.4807),0) -> 101377 | N2: 150000
A3: Number of Active Users | B3: 5% churn | C3: 2000 | D3: =D2-(C3*0.05) -> 2862 | E3: =E2-(D3*0.05) -> 4242.9 | F3: =F2-(E3*0.05) -> 6282.855 | G3: =G2-(F3*0.05) -> 9303.8573 | H3: =H2-(G3*0.05) -> 13776.807 | I3: =I2-(H3*0.05) -> 20400.16 | J3: =J2-(I3*0.05) -> 30206.992 | K3: =K2-(J3*0.05) -> 44727.65 | ... N3: =N2-(M3*0.05) -> 145096.72
A5: Card Sales
A6: Price charged per card | B6: Charge for selling the visa card to the user | C6: ='Fee Structure'!$B$2 -> 24.99 | D6: ='Fee Structure'!$B$2 -> 24.99 | E6: ='Fee Structure'!$B$2 -> 24.99 | F6: ='Fee Structure'!$B$2 -> 24.99 | G6: ='Fee Structure'!$B$2 -> 24.99 | H6: ='Fee Structure'!$B$2 -> 24.99 | I6: ='Fee Structure'!$B$2 -> 24.99 | J6: ='Fee Structure'!$B$2 -> 24.99 | ... N6: ='Fee Structure'!$B$2 -> 24.99
A7: Number of cards sold | B7: Number of new visa card sold / new users onboarded | C7: =C2-Dashboard!B16 -> 0 | D7: =D2-C2 -> 962 | E7: =E2-D2 -> 1424 | F7: =F2-E2 -> 2109 | G7: =G2-F2 -> 3123 | H7: =H2-G2 -> 4624 | I7: =I2-H2 -> 6847 | J7: =J2-I2 -> 10138 | K7: =K2-J2 -> 15011 | ... N7: =N2-M2 -> 48623
A8: Per User Card Sales Revenue | C8: =C6 -> 24.99 | D8: =D6 -> 24.99 | E8: =E6 -> 24.99 | F8: =F6 -> 24.99 | G8: =G6 -> 24.99 | H8: =H6 -> 24.99 | I8: =I6 -> 24.99 | J8: =J6 -> 24.99 | ... N8: =N6 -> 24.99
A9: Total Card Sales Revenue | C9: =C8*C7 -> 0 | D9: =D8*D7 -> 24040.38 | E9: =E8*E7 -> 35585.76 | F9: =F8*F7 -> 52703.91 | G9: =G8*G7 -> 78043.77 | H9: =H8*H7 -> 115553.76 | I9: =I8*I7 -> 171106.53 | J9: =J8*J7 -> 253348.62 | ... N9: =N8*N7 -> 1215088.8
A11: On Ramp
A12: Number of on ramp tx | B12: as per data from tangem | C12: 0 | D12: 1.5 | E12: 1.5 | F12: 1.5 | G12: 1.5 | H12: 1.5 | I12: 1.5 | J12: 1.5 | K12: 1.5 | L12: 1.5 | M12: 1.5 | N12: 1.5
A13: Average on ramp tx amount | B13: as per data from tangem | C13: 0 | D13: 400 | E13: 400 | F13: 400 | G13: 400 | H13: 400 | I13: 400 | J13: 400 | K13: 400 | L13: 400 | M13: 400 | N13: 400
A14: % of tx through card payment | C14: 0.9 | D14: 0.9 | E14: 0.9 | F14: 0.9 | G14: 0.9 | H14: 0.9 | I14: 0.9 | J14: 0.9 | K14: 0.9 | L14: 0.9 | M14: 0.9 | N14: 0.9
A15: % of tx through bank transfer | C15: =1-C14 -> 0.1 | D15: =1-D14 -> 0.1 | E15: =1-E14 -> 0.1 | F15: =1-F14 -> 0.1 | G15: =1-G14 -> 0.1 | H15: =1-H14 -> 0.1 | I15: =1-I14 -> 0.1 | J15: =1-J14 -> 0.1 | ... N15: =1-N14 -> 0.1
A16: % commision charged on card on ramp | B16: Charge for minting EURm by card payment | C16: ='Fee Structure'!$B$3 -> 0 | D16: ='Fee Structure'!$B$3 -> 0 | E16: ='Fee Structure'!$B$3 -> 0 | F16: ='Fee Structure'!$B$3 -> 0 | G16: ='Fee Structure'!$B$3 -> 0 | H16: ='Fee Structure'!$B$3 -> 0 | I16: ='Fee Structure'!$B$3 -> 0 | J16: ='Fee Structure'!$B$3 -> 0 | ... N16: ='Fee Structure'!$B$3 -> 0
A17: Commision earned on card on ramp | C17: =C12*C13*C14*C16 -> 0 | D17: =D12*D13*D14*D16 -> 0 | E17: =E12*E13*E14*E16 -> 0 | F17: =F12*F13*F14*F16 -> 0 | G17: =G12*G13*G14*G16 -> 0 | H17: =H12*H13*H14*H16 -> 0 | I17: =I12*I13*I14*I16 -> 0 | J17: =J12*J13*J14*J16 -> 0 | ... N17: =N12*N13*N14*N16 -> 0
A18: % commision charged on bank transfer on ramp | B18: Charge for minting EURm by bank transfer | C18: ='Fee Structure'!$B$4 -> 0 | D18: ='Fee Structure'!$B$4 -> 0 | E18: ='Fee Structure'!$B$4 -> 0 | F18: ='Fee Structure'!$B$4 -> 0 | G18: ='Fee Structure'!$B$4 -> 0 | H18: ='Fee Structure'!$B$4 -> 0 | I18: ='Fee Structure'!$B$4 -> 0 | J18: ='Fee Structure'!$B$4 -> 0 | ... N18: ='Fee Structure'!$B$4 -> 0
A19: Commision earned on bank transfer on ramp | C19: =C12*C13*C15*C18 -> 0 | D19: =D12*D13*D15*D18 -> 0 | E19: =E12*E13*E15*E18 -> 0 | F19: =F12*F13*F15*F18 -> 0 | G19: =G12*G13*G15*G18 -> 0 | H19: =H12*H13*H15*H18 -> 0 | I19: =I12*I13*I15*I18 -> 0 | J19: =J12*J13*J15*J18 -> 0 | ... N19: =N12*N13*N15*N18 -> 0
A20: Per User On Ramp Revenue | C20: =C17+C19 -> 0 | D20: =D17+D19 -> 0 | E20: =E17+E19 -> 0 | F20: =F17+F19 -> 0 | G20: =G17+G19 -> 0 | H20: =H17+H19 -> 0 | I20: =I17+I19 -> 0 | J20: =J17+J19 -> 0 | ... N20: =N17+N19 -> 0
A21: Total On Ramp Revenue | C21: =C20*C3 -> 0 | D21: =D20*D3 -> 0 | E21: =E20*E3 -> 0 | F21: =F20*F3 -> 0 | G21: =G20*G3 -> 0 | H21: =H20*H3 -> 0 | I21: =I20*I3 -> 0 | J21: =J20*J3 -> 0 | ... N21: =N20*N3 -> 0
A23: Swap Crypto to Crypto
A24: Number of swap tx | C24: 2 | D24: 2 | E24: 2 | F24: 2 | G24: 2 | H24: 2 | I24: 2 | J24: 2 | K24: 2 | L24: 2 | M24: 2 | N24: 2
A25: Average swap tx amount | C25: 100 | D25: 100 | E25: 100 | F25: 100 | G25: 100 | H25: 100 | I25: 100 | J25: 100 | K25: 100 | L25: 100 | M25: 100 | N25: 100
A26: % commision charged on swap | C26: ='Fee Structure'!$B$5 -> 0.00875 | D26: ='Fee Structure'!$B$5 -> 0.00875 | E26: ='Fee Structure'!$B$5 -> 0.00875 | F26: ='Fee Structure'!$B$5 -> 0.00875 | G26: ='Fee Structure'!$B$5 -> 0.00875 | H26: ='Fee Structure'!$B$5 -> 0.00875 | I26: ='Fee Structure'!$B$5 -> 0.00875 | J26: ='Fee Structure'!$B$5 -> 0.00875 | ... N26: ='Fee Structure'!$B$5 -> 0.00875
A27: Commision earned on swap | C27: =C24*C25*C26 -> 1.75 | D27: =D24*D25*D26 -> 1.75 | E27: =E24*E25*E26 -> 1.75 | F27: =F24*F25*F26 -> 1.75 | G27: =G24*G25*G26 -> 1.75 | H27: =H24*H25*H26 -> 1.75 | I27: =I24*I25*I26 -> 1.75 | J27: =J24*J25*J26 -> 1.75 | ... N27: =N24*N25*N26 -> 1.75
A28: Per User Swap Revenue | C28: =C27 -> 1.75 | D28: =D27 -> 1.75 | E28: =E27 -> 1.75 | F28: =F27 -> 1.75 | G28: =G27 -> 1.75 | H28: =H27 -> 1.75 | I28: =I27 -> 1.75 | J28: =J27 -> 1.75 | ... N28: =N27 -> 1.75
A29: Total Swap Revenue | C29: =C28*C3 -> 3500 | D29: =D28*D3 -> 5008.5 | E29: =E28*E3 -> 7425.075 | F29: =F28*F3 -> 10994.996 | G29: =G28*G3 -> 16281.75 | H29: =H28*H3 -> 24109.412 | I29: =I28*I3 -> 35700.279 | J29: =J28*J3 -> 52862.236 | ... N29: =N28*N3 -> 253919.26
A31: Off Ramp (Card Payment)
A32: Number of card payments | B32: SaltPay Iceland = 24 tx / month (25% through oly - 83% card, 17% bank) | C32: 6 | D32: 6 | E32: 6 | F32: 6 | G32: 6 | H32: 6 | I32: 6 | J32: 6 | K32: 6 | L32: 6 | M32: 6 | N32: 6
A33: Average card payment amount | B33: SaltPay Iceland = $40 Average | C33: 40 | D33: 40 | E33: 40 | F33: 40 | G33: 40 | H33: 40 | I33: 40 | J33: 40 | K33: 40 | L33: 40 | M33: 40 | N33: 40
A34: % commision charged on card payment | C34: ='Fee Structure'!$B$7 -> 0.01 | D34: ='Fee Structure'!$B$7 -> 0.01 | E34: ='Fee Structure'!$B$7 -> 0.01 | F34: ='Fee Structure'!$B$7 -> 0.01 | G34: ='Fee Structure'!$B$7 -> 0.01 | H34: ='Fee Structure'!$B$7 -> 0.01 | I34: ='Fee Structure'!$B$7 -> 0.01 | J34: ='Fee Structure'!$B$7 -> 0.01 | ... N34: ='Fee Structure'!$B$7 -> 0.01
A35: Commision earned on card payment | C35: =C32*C33*C34 -> 2.4 | D35: =D32*D33*D34 -> 2.4 | E35: =E32*E33*E34 -> 2.4 | F35: =F32*F33*F34 -> 2.4 | G35: =G32*G33*G34 -> 2.4 | H35: =H32*H33*H34 -> 2.4 | I35: =I32*I33*I34 -> 2.4 | J35: =J32*J33*J34 -> 2.4 | ... N35: =N32*N33*N34 -> 2.4
A36: % interchange charged on card payment | C36: ='Fee Structure'!$B$6 -> 0.002 | D36: ='Fee Structure'!$B$6 -> 0.002 | E36: ='Fee Structure'!$B$6 -> 0.002 | F36: ='Fee Structure'!$B$6 -> 0.002 | G36: ='Fee Structure'!$B$6 -> 0.002 | H36: ='Fee Structure'!$B$6 -> 0.002 | I36: ='Fee Structure'!$B$6 -> 0.002 | J36: ='Fee Structure'!$B$6 -> 0.002 | ... N36: ='Fee Structure'!$B$6 -> 0.002
A37: Interchange earned on card payment | C37: =C32*C33*C36 -> 0.48 | D37: =D32*D33*D36 -> 0.48 | E37: =E32*E33*E36 -> 0.48 | F37: =F32*F33*F36 -> 0.48 | G37: =G32*G33*G36 -> 0.48 | H37: =H32*H33*H36 -> 0.48 | I37: =I32*I33*I36 -> 0.48 | J37: =J32*J33*J36 -> 0.48 | ... N37: =N32*N33*N36 -> 0.48
A38: Per User Off Ramp (Card) Revenue | C38: =C35+C37 -> 2.88 | D38: =D35+D37 -> 2.88 | E38: =E35+E37 -> 2.88 | F38: =F35+F37 -> 2.88 | G38: =G35+G37 -> 2.88 | H38: =H35+H37 -> 2.88 | I38: =I35+I37 -> 2.88 | J38: =J35+J37 -> 2.88 | ... N38: =N35+N37 -> 2.88
A39: Total Off Ramp (Card) Revenue | C39: =C38*C3 -> 5760 | D39: =D38*D3 -> 8242.56 | E39: =E38*E3 -> 12219.552 | F39: =F38*F3 -> 18094.622 | G39: =G38*G3 -> 26795.109 | H39: =H38*H3 -> 39677.205 | I39: =I38*I3 -> 58752.46 | J39: =J38*J3 -> 86996.137 | ... N39: =N38*N3 -> 417878.56
A41: Off Ramp (Bank Transfer)
A42: Number of bank transfers | B42: SaltPay Iceland = 24 tx / month (25% through oly - 83% card, 17% bank) | C42: 0 | D42: 0 | E42: 0 | F42: 0 | G42: 0 | H42: 0 | I42: 0 | J42: 0 | K42: 0 | L42: 0 | M42: 0 | N42: 0
A43: Average bank transfer amount | B43: SaltPay Iceland = $40 Average | C43: 40 | D43: 40 | E43: 40 | F43: 40 | G43: 40 | H43: 40 | I43: 40 | J43: 40 | K43: 40 | L43: 40 | M43: 40 | N43: 40
A44: % commision charged on bank transfer | C44: ='Fee Structure'!$B$7 -> 0.01 | D44: ='Fee Structure'!$B$7 -> 0.01 | E44: ='Fee Structure'!$B$7 -> 0.01 | F44: ='Fee Structure'!$B$7 -> 0.01 | G44: ='Fee Structure'!$B$7 -> 0.01 | H44: ='Fee Structure'!$B$7 -> 0.01 | I44: ='Fee Structure'!$B$7 -> 0.01 | J44: ='Fee Structure'!$B$7 -> 0.01 | ... N44: ='Fee Structure'!$B$7 -> 0.01
A45: Commision earned on bank transfer | C45: =C42*C43*C44 -> 0 | D45: =D42*D43*D44 -> 0 | E45: =E42*E43*E44 -> 0 | F45: =F42*F43*F44 -> 0 | G45: =G42*G43*G44 -> 0 | H45: =H42*H43*H44 -> 0 | I45: =I42*I43*I44 -> 0 | J45: =J42*J43*J44 -> 0 | ... N45: =N42*N43*N44 -> 0
...

Sheet Direct Costs
A1: Particulars | B1: Assumption | C1: Jan-23 | D1: Feb-23 | E1: Mar-23 | F1: Apr-23 | G1: May-23 | H1: Jun-23 | I1: Jul-23 | J1: Aug-23 | K1: Sep-23 | L1: Oct-23 | M1: Nov-23 | N1: Dec-23
A2: Number of Users | B2: Growing at a rate of 48.07% | C2: 2000 | D2: =ROUNDUP((C2*1.4807),0) -> 2962 | E2: =ROUNDUP((D2*1.4807),0) -> 4386 | F2: =ROUNDUP((E2*1.4807),0) -> 6495 | G2: =ROUNDUP((F2*1.4807),0) -> 9618 | H2: =ROUNDUP((G2*1.4807),0) -> 14242 | I2: =ROUNDUP((H2*1.4807),0) -> 21089 | J2: =ROUNDUP((I2*1.4807),0) -> 31227 | K2: =ROUNDUP((J2*1.4807),0) -> 46238 | ... M2: =ROUNDUP((L2*1.4807),0) -> 101377 | N2: 150000
A3: Number of Active Users | B3: 5% churn | C3: 2000 | D3: =D2-(C3*0.05) -> 2862 | E3: =E2-(D3*0.05) -> 4242.9 | F3: =F2-(E3*0.05) -> 6282.855 | G3: =G2-(F3*0.05) -> 9303.8573 | H3: =H2-(G3*0.05) -> 13776.807 | I3: =I2-(H3*0.05) -> 20400.16 | J3: =J2-(I3*0.05) -> 30206.992 | K3: =K2-(J3*0.05) -> 44727.65 | ... N3: =N2-(M3*0.05) -> 145096.72
A5: Card Sales
A6: Number of cards sold | B6: Number of new visa card sold / new users onboarded | C6: =C2 -> 2000 | D6: =D2-C2 -> 962 | E6: =E2-D2 -> 1424 | F6: =F2-E2 -> 2109 | G6: =G2-F2 -> 3123 | H6: =H2-G2 -> 4624 | I6: =I2-H2 -> 6847 | J6: =J2-I2 -> 10138 | K6: =K2-J2 -> 15011 | ... N6: =N2-M2 -> 48623
A7: Prosuction cost per card | B7: As per data from Tangem | C7: ='Cost Structure'!$B13 -> 5.154 | D7: ='Cost Structure'!$B13 -> 5.154 | E7: ='Cost Structure'!$B13 -> 5.154 | F7: ='Cost Structure'!$B13 -> 5.154 | G7: ='Cost Structure'!$B13 -> 5.154 | H7: ='Cost Structure'!$B13 -> 5.154 | I7: ='Cost Structure'!$B13 -> 5.154 | J7: ='Cost Structure'!$B13 -> 5.154 | ... N7: ='Cost Structure'!$B13 -> 5.154
A8: Packaging cost per card | B8: As per data from Tangem | C8: ='Cost Structure'!$B14 -> 2.2 | D8: ='Cost Structure'!$B14 -> 2.2 | E8: ='Cost Structure'!$B14 -> 2.2 | F8: ='Cost Structure'!$B14 -> 2.2 | G8: ='Cost Structure'!$B14 -> 2.2 | H8: ='Cost Structure'!$B14 -> 2.2 | I8: ='Cost Structure'!$B14 -> 2.2 | J8: ='Cost Structure'!$B14 -> 2.2 | ... N8: ='Cost Structure'!$B14 -> 2.2
A9: Logistics cost per card | B9: As per data from Tangem | C9: ='Cost Structure'!$B15 -> 5 | D9: ='Cost Structure'!$B15 -> 5 | E9: ='Cost Structure'!$B15 -> 5 | F9: ='Cost Structure'!$B15 -> 5 | G9: ='Cost Structure'!$B15 -> 5 | H9: ='Cost Structure'!$B15 -> 5 | I9: ='Cost Structure'!$B15 -> 5 | J9: ='Cost Structure'!$B15 -> 5 | ... N9: ='Cost Structure'!$B15 -> 5
A10: Per Card Cost | C10: =SUM(C7:C9) -> 12.354 | D10: =SUM(D7:D9) -> 12.354 | E10: =SUM(E7:E9) -> 12.354 | F10: =SUM(F7:F9) -> 12.354 | G10: =SUM(G7:G9) -> 12.354 | H10: =SUM(H7:H9) -> 12.354 | I10: =SUM(I7:I9) -> 12.354 | J10: =SUM(J7:J9) -> 12.354 | ... N10: =SUM(N7:N9) -> 12.354
A11: Total Card Sales Cost | C11: =C10*C$6 -> 24708 | D11: =D10*D$6 -> 11884.548 | E11: =E10*E$6 -> 17592.096 | F11: =F10*F$6 -> 26054.586 | G11: =G10*G$6 -> 38581.542 | H11: =H10*H$6 -> 57124.896 | I11: =I10*I$6 -> 84587.838 | J11: =J10*J$6 -> 125244.85 | ... N11: =N10*N$6 -> 600688.54
A13: On Ramp
A14: Number of on ramp tx | C14: ='Revenues'!C12 -> 0 | D14: ='Revenues'!D12 -> 1.5 | E14: ='Revenues'!E12 -> 1.5 | F14: ='Revenues'!F12 -> 1.5 | G14: ='Revenues'!G12 -> 1.5 | H14: ='Revenues'!H12 -> 1.5 | I14: ='Revenues'!I12 -> 1.5 | J14: ='Revenues'!J12 -> 1.5 | ... N14: ='Revenues'!N12 -> 1.5
A15: Average on ramp tx amount | C15: ='Revenues'!C13 -> 0 | D15: ='Revenues'!D13 -> 400 | E15: ='Revenues'!E13 -> 400 | F15: ='Revenues'!F13 -> 400 | G15: ='Revenues'!G13 -> 400 | H15: ='Revenues'!H13 -> 400 | I15: ='Revenues'!I13 -> 400 | J15: ='Revenues'!J13 -> 400 | ... N15: ='Revenues'!N13 -> 400
A16: % of tx through card payment | C16: ='Revenues'!C14 -> 0.9 | D16: ='Revenues'!D14 -> 0.9 | E16: ='Revenues'!E14 -> 0.9 | F16: ='Revenues'!F14 -> 0.9 | G16: ='Revenues'!G14 -> 0.9 | H16: ='Revenues'!H14 -> 0.9 | I16: ='Revenues'!I14 -> 0.9 | J16: ='Revenues'!J14 -> 0.9 | ... N16: ='Revenues'!N14 -> 0.9
A17: % of tx through bank transfer | C17: =1-C16 -> 0.1 | D17: =1-D16 -> 0.1 | E17: =1-E16 -> 0.1 | F17: =1-F16 -> 0.1 | G17: =1-G16 -> 0.1 | H17: =1-H16 -> 0.1 | I17: =1-I16 -> 0.1 | J17: =1-J16 -> 0.1 | ... N17: =1-N16 -> 0.1
A18: % Cost of card payment | C18: ='Cost Structure'!$B$2 -> 0 | D18: ='Cost Structure'!$B$2 -> 0 | E18: ='Cost Structure'!$B$2 -> 0 | F18: ='Cost Structure'!$B$2 -> 0 | G18: ='Cost Structure'!$B$2 -> 0 | H18: ='Cost Structure'!$B$2 -> 0 | I18: ='Cost Structure'!$B$2 -> 0 | J18: ='Cost Structure'!$B$2 -> 0 | ... N18: ='Cost Structure'!$B$2 -> 0
A19: Cost incurred for card payment on ramp | C19: =C14*C15*C16*C18 -> 0 | D19: =D14*D15*D16*D18 -> 0 | E19: =E14*E15*E16*E18 -> 0 | F19: =F14*F15*F16*F18 -> 0 | G19: =G14*G15*G16*G18 -> 0 | H19: =H14*H15*H16*H18 -> 0 | I19: =I14*I15*I16*I18 -> 0 | J19: =J14*J15*J16*J18 -> 0 | ... N19: =N14*N15*N16*N18 -> 0
A20: % Cost of bank transfer | C20: ='Cost Structure'!$B$2 -> 0 | D20: ='Cost Structure'!$B$2 -> 0 | E20: ='Cost Structure'!$B$2 -> 0 | F20: ='Cost Structure'!$B$2 -> 0 | G20: ='Cost Structure'!$B$2 -> 0 | H20: ='Cost Structure'!$B$2 -> 0 | I20: ='Cost Structure'!$B$2 -> 0 | J20: ='Cost Structure'!$B$2 -> 0 | ... N20: ='Cost Structure'!$B$2 -> 0
A21: Cost incurred for bank transfer on ramp | C21: =C14*C15*C17*C20 -> 0 | D21: =D14*D15*D17*D20 -> 0 | E21: =E14*E15*E17*E20 -> 0 | F21: =F14*F15*F17*F20 -> 0 | G21: =G14*G15*G17*G20 -> 0 | H21: =H14*H15*H17*H20 -> 0 | I21: =I14*I15*I17*I20 -> 0 | J21: =J14*J15*J17*J20 -> 0 | ... N21: =N14*N15*N17*N20 -> 0
A22: Per User On Ramp Cost | C22: =C19+C21 -> 0 | D22: =D19+D21 -> 0 | E22: =E19+E21 -> 0 | F22: =F19+F21 -> 0 | G22: =G19+G21 -> 0 | H22: =H19+H21 -> 0 | I22: =I19+I21 -> 0 | J22: =J19+J21 -> 0 | ... N22: =N19+N21 -> 0
A23: Total On Ramp Cost | C23: =C22*C$2 -> 0 | D23: =D22*D$3 -> 0 | E23: =E22*E$3 -> 0 | F23: =F22*F$3 -> 0 | G23: =G22*G$3 -> 0 | H23: =H22*H$3 -> 0 | I23: =I22*I$3 -> 0 | J23: =J22*J$3 -> 0 | K23: =K22*K$3 -> 0 | ... N23: =N22*N$3 -> 0
A25: Swap Crypto to Crypto
A26: Number of swap tx | C26: ='Revenues'!C24 -> 2 | D26: ='Revenues'!D24 -> 2 | E26: ='Revenues'!E24 -> 2 | F26: ='Revenues'!F24 -> 2 | G26: ='Revenues'!G24 -> 2 | H26: ='Revenues'!H24 -> 2 | I26: ='Revenues'!I24 -> 2 | J26: ='Revenues'!J24 -> 2 | ... N26: ='Revenues'!N24 -> 2
A27: Average swap tx amount | C27: ='Revenues'!C25 -> 100 | D27: ='Revenues'!D25 -> 100 | E27: ='Revenues'!E25 -> 100 | F27: ='Revenues'!F25 -> 100 | G27: ='Revenues'!G25 -> 100 | H27: ='Revenues'!H25 -> 100 | I27: ='Revenues'!I25 -> 100 | J27: ='Revenues'!J25 -> 100 | ... N27: ='Revenues'!N25 -> 100
A28: % Cost of crypto swap | B28: no cost | C28: ='Cost Structure'!$B$3 -> 0 | D28: ='Cost Structure'!$B$3 -> 0 | E28: ='Cost Structure'!$B$3 -> 0 | F28: ='Cost Structure'!$B$3 -> 0 | G28: ='Cost Structure'!$B$3 -> 0 | H28: ='Cost Structure'!$B$3 -> 0 | I28: ='Cost Structure'!$B$3 -> 0 | J28: ='Cost Structure'!$B$3 -> 0 | ... N28: ='Cost Structure'!$B$3 -> 0
A29: Cost incurred on swap | C29: =C26*C27*C28 -> 0 | D29: =D26*D27*D28 -> 0 | E29: =E26*E27*E28 -> 0 | F29: =F26*F27*F28 -> 0 | G29: =G26*G27*G28 -> 0 | H29: =H26*H27*H28 -> 0 | I29: =I26*I27*I28 -> 0 | J29: =J26*J27*J28 -> 0 | ... N29: =N26*N27*N28 -> 0
A30: Per User Swap Cost | C30: =C29 -> 0 | D30: =D29 -> 0 | E30: =E29 -> 0 | F30: =F29 -> 0 | G30: =G29 -> 0 | H30: =H29 -> 0 | I30: =I29 -> 0 | J30: =J29 -> 0 | ... N30: =N29 -> 0
A31: Total Swap Cost | C31: =C30*C$2 -> 0 | D31: =D30*D$2 -> 0 | E31: =E30*E$2 -> 0 | F31: =F30*F$2 -> 0 | G31: =G30*G$2 -> 0 | H31: =H30*H$2 -> 0 | I31: =I30*I$2 -> 0 | J31: =J30*J$2 -> 0 | ... N31: =N30*N$2 -> 0
A33: Off Ramp (Card Payment)
A34: Number of card payments | B34: SaltPay Iceland = 20 tx / month (25% through oly card) | C34: ='Revenues'!C32 -> 6 | D34: ='Revenues'!D32 -> 6 | E34: ='Revenues'!E32 -> 6 | F34: ='Revenues'!F32 -> 6 | G34: ='Revenues'!G32 -> 6 | H34: ='Revenues'!H32 -> 6 | I34: ='Revenues'!I32 -> 6 | J34: ='Revenues'!J32 -> 6 | ... N34: ='Revenues'!N32 -> 6
A35: Average card payment amount | B35: SaltPay Iceland = $40 Average | C35: ='Revenues'!C33 -> 40 | D35: ='Revenues'!D33 -> 40 | E35: ='Revenues'!E33 -> 40 | F35: ='Revenues'!F33 -> 40 | G35: ='Revenues'!G33 -> 40 | H35: ='Revenues'!H33 -> 40 | I35: ='Revenues'!I33 -> 40 | J35: ='Revenues'!J33 -> 40 | ... N35: ='Revenues'!N33 -> 40
A36: % cost on card payment | B36: Paymentology | C36: ='Cost Structure'!$B$4 -> 0.0005 | D36: ='Cost Structure'!$B$4 -> 0.0005 | E36: ='Cost Structure'!$B$4 -> 0.0005 | F36: ='Cost Structure'!$B$4 -> 0.0005 | G36: ='Cost Structure'!$B$4 -> 0.0005 | H36: ='Cost Structure'!$B$4 -> 0.0005 | I36: ='Cost Structure'!$B$4 -> 0.0005 | J36: ='Cost Structure'!$B$4 -> 0.0005 | ... N36: ='Cost Structure'!$B$4 -> 0.0005
A37: Cost incurred on card payment | C37: =C34*C35*C36 -> 0.12 | D37: =D34*D35*D36 -> 0.12 | E37: =E34*E35*E36 -> 0.12 | F37: =F34*F35*F36 -> 0.12 | G37: =G34*G35*G36 -> 0.12 | H37: =H34*H35*H36 -> 0.12 | I37: =I34*I35*I36 -> 0.12 | J37: =J34*J35*J36 -> 0.12 | ... N37: =N34*N35*N36 -> 0.12
A38: Per User Off Ramp (Card) Cost | C38: =C37 -> 0.12 | D38: =D37 -> 0.12 | E38: =E37 -> 0.12 | F38: =F37 -> 0.12 | G38: =G37 -> 0.12 | H38: =H37 -> 0.12 | I38: =I37 -> 0.12 | J38: =J37 -> 0.12 | ... N38: =N37 -> 0.12
A39: Total Off Ramp (Card) Cost | C39: =C38*C$2 -> 240 | D39: =D38*D$2 -> 355.44 | E39: =E38*E$2 -> 526.32 | F39: =F38*F$2 -> 779.4 | G39: =G38*G$2 -> 1154.16 | H39: =H38*H$2 -> 1709.04 | I39: =I38*I$2 -> 2530.68 | J39: =J38*J$2 -> 3747.24 | ... N39: =N38*N$2 -> 18000
A41: Off Ramp (Bank Transfer)
A42: Number of bank transfers | C42: ='Revenues'!C42 -> 0 | D42: ='Revenues'!D42 -> 0 | E42: ='Revenues'!E42 -> 0 | F42: ='Revenues'!F42 -> 0 | G42: ='Revenues'!G42 -> 0 | H42: ='Revenues'!H42 -> 0 | I42: ='Revenues'!I42 -> 0 | J42: ='Revenues'!J42 -> 0 | ... N42: ='Revenues'!N42 -> 0
A43: Average bank transfer amount | C43: ='Revenues'!C43 -> 40 | D43: ='Revenues'!D43 -> 40 | E43: ='Revenues'!E43 -> 40 | F43: ='Revenues'!F43 -> 40 | G43: ='Revenues'!G43 -> 40 | H43: ='Revenues'!H43 -> 40 | I43: ='Revenues'!I43 -> 40 | J43: ='Revenues'!J43 -> 40 | ... N43: ='Revenues'!N43 -> 40
A44: % cost on bank transfer | C44: ='Cost Structure'!$B$5 -> 0.002 | D44: ='Cost Structure'!$B$5 -> 0.002 | E44: ='Cost Structure'!$B$5 -> 0.002 | F44: ='Cost Structure'!$B$5 -> 0.002 | G44: ='Cost Structure'!$B$5 -> 0.002 | H44: ='Cost Structure'!$B$5 -> 0.002 | I44: ='Cost Structure'!$B$5 -> 0.002 | J44: ='Cost Structure'!$B$5 -> 0.002 | ... N44: ='Cost Structure'!$B$5 -> 0.002
A45: Cost incurred on bank transfer | C45: =C42*C43*C44 -> 0 | D45: =D42*D43*D44 -> 0 | E45: =E42*E43*E44 -> 0 | F45: =F42*F43*F44 -> 0 | G45: =G42*G43*G44 -> 0 | H45: =H42*H43*H44 -> 0 | I45: =I42*I43*I44 -> 0 | J45: =J42*J43*J44 -> 0 | ... N45: =N42*N43*N44 -> 0
...

Sheet Oly CAPEX
A1: Particulars | B1: Assumption | C1: Jan-23 | D1: Feb-23 | E1: Mar-23 | F1: Apr-23 | G1: May-23 | H1: Jun-23 | I1: Jul-23 | J1: Aug-23 | K1: Sep-23 | L1: Oct-23 | M1: Nov-23 | N1: Dec-23
A3: Hardware
A4: Cloud Infrastructure | C4: 3000 | D4: =C4 -> 3000 | E4: =D4 -> 3000 | F4: =E4 -> 3000 | G4: =F4 -> 3000 | H4: =G4 -> 3000 | I4: =H4 -> 3000 | J4: =I4 -> 3000 | K4: =J4 -> 3000 | ... N4: =M4 -> 3000
A5: Development Site | C5: 1250 | D5: 1250 | E5: 1250 | F5: 1250 | G5: 1250 | H5: 1250 | I5: 1250 | J5: 1250 | K5: 1250 | L5: 1250 | M5: 1250 | N5: 1250
A6: IT Infrastructure | C6: 16000
A7: Total Hardware | C7: =SUM(C4:C6) -> 20250 | D7: =SUM(D4:D5) -> 4250 | E7: =SUM(E4:E5) -> 4250 | F7: =SUM(F4:F5) -> 4250 | G7: =SUM(G4:G5) -> 4250 | H7: =SUM(H4:H5) -> 4250 | I7: =SUM(I4:I5) -> 4250 | J7: =SUM(J4:J5) -> 4250 | K7: =SUM(K4:K5) -> 4250 | ... N7: =SUM(N4:N5) -> 4250
A9: Software
A10: MC Chip development | C10: 30000 | D10: 0 | E10: 30000 | F10: 0 | G10: 30000 | H10: 0 | I10: 30000 | J10: 0 | K10: 30000 | L10: 0 | M10: 0 | N10: 0
A11: Chip application development | C11: 12500 | D11: 0 | E11: 0 | F11: 12500 | G11: 0 | H11: 0 | I11: 12500 | J11: 0 | K11: 0 | L11: 12500 | M11: 0 | N11: 0
A12: Total Software | C12: =SUM(C10:C11) -> 42500 | D12: =SUM(D10:D11) -> 0 | E12: =SUM(E10:E11) -> 30000 | F12: =SUM(F10:F11) -> 12500 | G12: =SUM(G10:G11) -> 30000 | H12: =SUM(H10:H11) -> 0 | I12: =SUM(I10:I11) -> 42500 | J12: =SUM(J10:J11) -> 0 | ... N12: =SUM(N10:N11) -> 0
A15: Brand
A16: Website creation and branding | C16: 40000
A18: Total CAPEX | C18: =+C7+C12+C16 -> 102750 | D18: =+D7+D12 -> 4250 | E18: =+E7+E12 -> 34250 | F18: =+F7+F12 -> 16750 | G18: =+G7+G12 -> 34250 | H18: =+H7+H12 -> 4250 | I18: =+I7+I12 -> 46750 | J18: =+J7+J12 -> 4250 | K18: =+K7+K12 -> 34250 | ... N18: =+N7+N12 -> 4250
