Workbook

Sheet Valuation
B2: Basic Information from Dune Analytics | H2: Valuation Summary of Nov/22 | T2: Appendix
B4: Month | C4: Total transaction fees | D4: Total transactions | E4: Active Account | F4: GNO Price | H4: Target PF ratio of Comparables in Nob/22 | I4: ='PF Ratio Comparables'!C24 -> 177.938 | T4: Year | U4: Apple card users | V4: Growth rate
B5: 44136 | C5: 544 | D5: 1100799 | E5: 12744 | F5: 41 | T5: 2019 | U5: 1600000
B6: 44166 | C6: 559 | D6: 1089356 | E6: 9654 | F6: 62 | H6: Last twleve month active users | I6: =AVERAGE(E5:E29) -> 105704.68 | T6: 2020 | U6: 3100000 | V6: =(U6/U5)-1 -> 0.9375
B7: 44197 | C7: 2197 | D7: 3185226 | E7: 12743 | F7: 75 | T7: 2021 | U7: 6400000 | V7: =(U7/U6)-1 -> 1.0645161
B8: 44228 | C8: 42558 | D8: 3011489 | E8: 40418 | F8: 112 | H8: Fees from Last Twelve Months | I8: =SUM(C17:C29) -> 1785105 | T8: 2022 | U8: 7700000 | V8: =(U8/U7)-1 -> 0.203125
B9: 44256 | C9: 129119 | D9: 4848266 | E9: 95853 | F9: 124 | H9: Fees from Last Twenty-Four Months/2 | I9: =SUM(C5:C29)/2 -> 2197384 | J9: *Assumption for 2021 fees | U9: Geo.Average | V9: =((1+V6)*(1+V7)*(1+V8))^(1/3)-1 -> 0.68832835
B10: 44287 | C10: 142163 | D10: 4215811 | E10: 47192 | F10: 170
B11: 44317 | C11: 533899 | D11: 7513673 | E11: 37597 | F11: 228 | H11: Average revenue per user (ARPU) | I11: =I9/I6 -> 20.787954
B12: 44348 | C12: 439345 | D12: 6891864 | E12: 501015 | F12: 187 | T12: VISA | U12: Revenue | V12: Growth
B13: 44378 | C13: 205642 | D13: 6622998 | E13: 320453 | F13: 162 | T13: 2012 | U13: 10421 | V13: =(U13-U14)/U14 -> 0.13419678
B14: 44409 | C14: 264627 | D14: 9090866 | E14: 471760 | F14: 193 | H14: Circulating supply | I14: 2579589 | T14: 2011 | U14: 9188 | V14: =(U14-U15)/U15 -> 0.13924365
B15: 44440 | C15: 566112 | D15: 7882158 | E15: 188412 | F15: 281 | H15: Total supply | I15: 3000000 | T15: 2010 | U15: 8065
B16: 44470 | C16: 282898 | D16: 7810838 | E16: 134708 | F16: 273
B17: 44501 | C17: 323745 | D17: 5603630 | E17: 100471 | F17: 449
B18: 44531 | C18: 388017 | D18: 6938242 | E18: 97704 | F18: 461 | H18: Market Cap (12) | I18: =I8*$I$4 -> 3.1763801e+08 | T18: MasterCard
B19: 44562 | C19: 413798 | D19: 5761675 | E19: 73811 | F19: 532 | H19: Market Cap (24/2) | I19: =I9*$I$4 -> 3.9099811e+08 | T19: 2012 | U19: 7391 | V19: =(U19-U20)/U20 -> 0.10083408
B20: 44593 | C20: 160551 | D20: 5047650 | E20: 76620 | F20: 294 | T20: 2011 | U20: 6714 | V20: =(U20-U21)/U21 -> 0.21213215
B21: 44621 | C21: 164057 | D21: 4455106 | E21: 80816 | F21: 354 | H21: 44887 | I21: Target price | T21: 2010 | U21: 5539
B22: 44652 | C22: 131290 | D22: 3871965 | E22: 54442 | F22: 421 | H22: Price of the token(12) | I22: =I18/$I$14 -> 123.13512
B23: 44682 | C23: 189690 | D23: 6164423 | E23: 51050 | F23: 309 | H23: Price of the token(24/2) | I23: =I19/$I$14 -> 151.5738 | J23: The thepry price of today
B24: 44713 | C24: 3949 | D24: 2218339 | E24: 35990 | F24: 204 | H24: Diluted Price of GNO(12) | I24: =I18/$I$15 -> 105.87934
B25: 44743 | C25: 1738 | D25: 1827330 | E25: 27776 | F25: 109 | H25: Diluted Price of GNO(24/2) | I25: =I19/$I$15 -> 130.3327
B26: 44774 | C26: 2801 | D26: 2133566 | E26: 27355 | F26: 160
B27: 44805 | C27: 2709 | D27: 2431087 | E27: 44407 | F27: 155
B28: 44835 | C28: 1327 | D28: 2974297 | E28: 78184 | F28: 119
B29: 44866 | C29: 1433 | D29: 1837668 | E29: 21442 | F29: 127
E32: Total Transactions last 90 days
E33: 7845282
E34: Active accounts in last 90 days
E35: 127428
E36: Transaction fees last 90 days
E37: 6127
B38: Link | E38: Today price | F38: 79
B42: Active Users projection | E42: Revenue
B44: ** Assumption for the card issueance from Oly project has the same growth rate as Apple Card
B45: Year | C45: User growth rate | D45: User | E45: Gnosis Revenue | F45: ARPU | G45: Revenue Growth Rate
B46: N+1 (2023) | C46: =Valuation!V6 -> 0.9375 | D46: =I6*(1+C46) -> 204802.82 | E46: 2913295.9 | F46: 14.224882 | G46: 0.32580193
B47: N+2 (2024) | C47: =Valuation!V7 -> 1.0645161 | D47: =D46*(1+C47) -> 422818.72 | E47: 3735458.6 | F47: 8.8346575 | G47: 0.28221047
B48: N+3 (2025) | C48: =Valuation!V8 -> 0.203125 | D48: =D47*(1+C48) -> 508703.77 | E48: 5825741.4 | F48: 11.452129 | G48: 0.55957864
...

Sheet PF Ratio Comparables
B2: PF Ratio comparables
B6: Selected
B7: Layer 1 | C7: Circulating Maket Cap | D7: Fully diluted Market Cap | E7: PS-fully diluted | F7: PS circulating | G7: PF Fully diluted | H7: PF circulating | I7: Annualized Fee | J7: Revenue past 365 days | K7: Revenue annualized (Onchain)
B8: Ethereum | H8: 114.8 | J8: 5100000000
B9: BSC | C9: 42010000000 | D9: 51460000000 | E9: 1896 | G9: 189.5 | H9: 154.8 | I9: 287450000 | J9: 52300000 | K9: 28720000
B10: Fantom | C10: 435500000 | D10: 544130000 | E10: 525 | G10: 157 | I10: 3710000 | J10: 7900000 | K10: 1100000
B12: Layer 2
B13: Optimism | C13: 177930000 | D13: 3560000000 | E13: 918 | G13: 204 | I13: 19520000 | J13: 5800000 | K13: 4350000
B14: Polygon | C14: 6980000000 | D14: 7870000000 | G14: 224.39 | I14: 39140000 | J14: 4600000 | K14: 15600000
B16: Gnosis | C16: 204992231 | D16: 238401037 | H16: =C16/I16 -> 114.83483 | I16: =Valuation!I8 -> 1785105 | K16: 15100000 | L16: ***Not reliable source
B17: Not Selected
B18: Solana | C18: 4280000000 | F18: 569 | H18: 284.81 | I18: 16440000 | K18: 8220000
B19: Polkadot | C19: 6090000000 | F19: 16294 | H19: 13035 | I19: 495555 | K19: 396440
B20: Avalanche | C20: 3570000000 | D20: 8550000000 | E20: 1257 | G20: 1257 | I20: 7380000 | K20: 7380000
B21: Tron
B22: Arbitrum | I22: 12710000 | J22: 7600000 | K22: 3260000
B24: Average | C24: =AVERAGE(H8,G9,G14,G13,G10) -> 177.938
B26: *P/F ratio: fully diluted market cap / annualized fees.
B27: ** Source: Token Terminal, CoinGecko
B33: Binance revenue
B34: 2020 | C34: 5.5B
B35: 2021 | C35: 20B

Sheet 3 Factors regression
B2: Three factors regression
B4: Regression Statistics
B5: Multiple R | C5: 0.67562504
B6: R Square | C6: 0.4564692 | D6: *The measure of how much change of the price is driven by other variables, Transaction fee, Total transactions and active accounts
B7: Adjusted R Square | C7: 0.37882194 | D7: **46% of the variation in price, good correlation
B8: Standard Error | C8: 105.69737
B9: Observations | C9: 25
B11: ANOVA
C12: df | D12: SS | E12: MS | F12: F | G12: Significance F
B13: Regression | C13: 3 | D13: 197031.2 | E13: 65677.068 | F13: 5.8787549 | G13: 0.0044530647 | H13: <0.05 | I13: ***Strong correlation
B14: Residual | C14: 21 | D14: 234610.64 | E14: 11171.935
B15: Total | C15: 24 | D15: 431641.84
C17: Coefficients | D17: Standard Error | E17: t Stat | F17: P-value | G17: Lower 95% | H17: Upper 95% | I17: Lower 95.0% | J17: Upper 95.0%
B18: Intercept | C18: 111.44255 | D18: 59.369034 | E18: 1.8771157 | F18: 0.074465342 | G18: -12.022118 | H18: 234.90721 | I18: -12.022118 | J18: 234.90721
B19: Total transaction fees | C19: 0.0003639193 | D19: 0.00024005685 | E19: 1.5159713 | F19: 0.14443566 | G19: -0.00013530624 | H19: 0.00086314484 | I19: -0.00013530624 | J19: 0.00086314484
B20: Total transactions | C20: 2.0472692e-05 | D20: 2.1503701e-05 | E20: 0.95205438 | F20: 0.35189975 | G20: -2.4246701e-05 | H20: 6.5192086e-05 | I20: -2.4246701e-05 | J20: 6.5192086e-05
B21: Active Account | C21: -0.00042689035 | D21: 0.00022262231 | E21: -1.9175542 | F21: 0.068870563 | G21: -0.00088985877 | H21: 3.6078083e-05 | I21: -0.00088985877 | J21: 3.6078083e-05
F22: >0.05 | G22: ****These three factors do not have an real effect on the price
B24: One Factor regression
B26: Regression Statistics
B27: Multiple R | C27: 0.60074943
B28: R Square | C28: 0.36089988 | D28: *The measure of how much change of the price is driven by other variable, Transaction fee
B29: Adjusted R Square | C29: 0.33311292 | D29: **36% of the variation in price, good correlation
B30: Standard Error | C30: 109.51719
B31: Observations | C31: 25
B33: ANOVA
C34: df | D34: SS | E34: MS | F34: F | G34: Significance F
B35: Regression | C35: 1 | D35: 155779.49 | E35: 155779.49 | F35: 12.988102 | G35: 0.0014956851 | H35: <0.05 | I35: ***Strong correlation
B36: Residual | C36: 23 | D36: 275862.35 | E36: 11994.015
B37: Total | C37: 24 | D37: 431641.84
C39: Coefficients | D39: Standard Error | E39: t Stat | F39: P-value | G39: Lower 95% | H39: Upper 95% | I39: Lower 95.0% | J39: Upper 95.0%
B40: Intercept | C40: 145.99795 | D40: 30.808689 | E40: 4.7388564 | F40: 8.9249564e-05 | G40: 82.265325 | H40: 209.73058 | I40: 82.265325 | J40: 209.73058
B41: Total transaction fees | C41: 0.00044417615 | D41: 0.00012324872 | E41: 3.6039009 | F41: 0.0014956851 | G41: 0.00018921676 | H41: 0.00069913555 | I41: 0.00018921676 | J41: 0.00069913555
F42: <0.05 | G42: The Transaction fee coefficient have an real effect on the price

Sheet Token terminal
A1: Token Terminal Master Excel SAMPLE DATA
B2: Price & Market cap | Q2: Total Value Locked (TVL) | AA2: GMV | AB2: Total revenue | AJ2: Protocol revenue | AR2: Price to sales (P/S) ratio | BB2: Twitter
A3: Project | B3: Symbol | C3: Launch date | D3: Category tags | E3: Price latest | F3: 24h change | G3: 7d change | H3: 30d change | I3: 90d change | J3: 180d change | K3: ATH | L3: ATL | M3: Volume 24h | N3: Circulating market cap latest | O3: Fully-diluted market cap latest | P3: Volume / MC ratio | Q3: TVL latest | R3: 24h change | S3: 7d change | T3: 30d change | U3: 90d change | V3: 180d change | W3: 7d avg. TVL | X3: 30d avg. TVL | Y3: 90d avg. TVL | Z3: 180d avg. TVL | AA3: Annualized GMV | AB3: 7d total revenue | AC3: 7d change | AD3: 30d total revenue | AE3: 30d change | AF3: 90d total revenue | AG3: 90d change | AH3: 180d total revenue | AI3: 180d change | AJ3: 7d protocol revenue | AK3: 7d change | AL3: 30d protocol revenue | AM3: 30d change | AN3: 90d protocol revenue | AO3: 90d change | AP3: 180d protocol revenue | AQ3: 180d change | AR3: P/S ratio latest | AS3: 24h change | AT3: 7d change | AU3: 30d change | AV3: 90d change | AW3: 180d change | AX3: 7d avg. P/S ratio | AY3: 30d avg. P/S ratio | AZ3: 90d avg. P/S ratio | BA3: 180d avg. P/S ratio | BB3: Twitter followers latest
A4: 0x | B4: ZRX | C4: 2017-08-15 | D4: DeFi Exchange | E4: 0.907061 | F4: 0.10703848 | G4: -0.40235191 | H4: -0.35046609 | I4: -0.4197824 | J4: 0.99653022 | K4: 2.5 | L4: 0.120667 | M4: 2.7001483e+08 | N4: 7.6501998e+08 | O4: 907061000 | P4: 0.30335273 | AA4: 1.6301887e+11 | AB4: 304258.26 | AC4: 0.096827208 | AD4: 1127205.2 | AE4: 1.2395466 | AF4: 2216957.2 | AG4: 0.58523423 | AH4: 3334105.2 | AI4: 23.478474 | AJ4: 304258.26 | AK4: 0.096827208 | AL4: 1127205.2 | AM4: 1.2395466 | AN4: 2216957.2 | AO4: 0.58523423 | AP4: 3334105.2 | AQ4: 23.478474 | AR4: 68.344306 | AS4: -0.097799426 | AT4: -0.31293775 | AU4: -0.66483615 | AV4: -0.70743155 | AW4: -0.7405759 | AX4: 99.473236 | AY4: 203.91312 | AZ4: 233.60108 | BA4: 263.44625 | BB4: 216397
A5: 88mph | B5: MPH | C5: 2019-10-10 | D5: DeFi Lending | E5: 46.97 | F5: 0.091601023 | G5: -0.5608729 | H5: -0.56405281 | I5: -0.56777604 | J5: 0.062370718 | K5: 236.5 | L5: 20.21 | M5: 1027323.9 | N5: 17269063 | O5: 18583868 | P5: 0.032602242 | Q5: 36197691 | R5: -0.033558483 | S5: -0.11415359 | T5: -0.17391465 | U5: 0.011792279 | V5: 0.58452993 | W5: 40862265 | X5: 43818343 | Y5: 35775813 | Z5: 22844435 | BB5: 11284
A6: Aave | B6: AAVE | C6: 2017-11-25 | D6: DeFi Lending | E6: 331.88 | F6: 0.15937335 | G6: -0.3963676 | H6: 0.0044495004 | I6: -0.1296904 | J6: 4.1241903 | K6: 661.69 | L6: 26.02 | M6: 1.4181195e+09 | N6: 4.1994751e+09 | O6: 5310080000 | P6: 0.18857959 | Q6: 1.050661e+10 | R6: -0.051021408 | S6: -0.15439516 | T6: -0.034643738 | U6: 0.42553116 | V6: 1.0924891 | W6: 1.2424965e+10 | X6: 1.0883661e+10 | Y6: 7.3703125e+09 | Z6: 5.0211062e+09 | AA6: 5.5005466e+09 | AB6: 8129873.6 | AC6: 0.15120587 | AD6: 32423093 | AE6: 1.4837325 | AF6: 55098785 | AG6: 2.3932115 | AH6: 70425502 | AI6: 29.709802 | AJ6: 760441.98 | AK6: 0.18732081 | AL6: 2986505.5 | AM6: 2.5899863 | AN6: 4425182.8 | AO6: 6.2983902 | AP6: 4994487.5 | AQ6: 101.00346 | AR6: 13.909626 | AS6: -0.09091701 | AT6: -0.34089114 | AU6: -0.56422243 | AV6: -0.66893696 | AW6: -0.75651965 | AX6: 21.103685 | AY6: 31.919095 | AZ6: 42.015037 | BA6: 57.128331 | BB6: 214534
A7: Alchemix Finance | B7: ALCX | C7: 2021-01-22 | D7: Asset Management DeFi Lending Stablecoin | E7: 743.64 | F7: 0.021960944 | G7: -0.42644238 | H7: -0.44088072 | K7: 2066.2 | L7: 279.54 | M7: 13907026 | N7: 2.0807814e+08 | O7: 1.7795751e+09 | P7: 0.0066225113 | Q7: 1.071144e+09 | R7: -0.026839883 | S7: -0.1234801 | T7: -0.19994347 | U7: -0.033765659 | V7: -0.033765659 | W7: 1.2220418e+09 | X7: 1.3388354e+09 | Y7: 1.1085758e+09 | Z7: 1.1085758e+09 | BB7: 29238
A8: Autofarm | B8: AUTO | C8: 2020-04-23 | D8: Asset Management DeFi | E8: 1299.56 | F8: 0.1035277 | G8: -0.49749179 | H8: -0.42671596 | I8: -0.8422835 | M8: 8204246.8 | N8: 32857026 | O8: 103964800 | P8: 0.11919149 | Q8: 9.5969067e+08 | R8: -0.06254338 | S8: -0.22997534 | T8: -0.31602927 | U8: -0.33943608 | V8: -0.34102515 | W8: 1.2463116e+09 | X8: 1.4031166e+09 | Y8: 1.4528354e+09 | Z8: 1.4563388e+09 | BB8: 63514
A9: Balancer | B9: BAL | C9: 2020-06-20 | D9: DeFi Exchange | E9: 28.34 | F9: 0.078847702 | G9: -0.4517283 | H9: -0.41477158 | I9: -0.25351982 | J9: 0.84923798 | K9: 74.45 | L9: 6.65 | M9: 79185559 | N9: 3.0481911e+08 | O9: 2834000000 | P9: 0.017410493 | Q9: 2.4074436e+09 | R9: -0.0446621 | S9: -0.16877407 | T9: -0.22178452 | U9: -0.027803483 | V9: 0.43615639 | W9: 2.8962566e+09 | X9: 3.0935436e+09 | Y9: 2.4762931e+09 | Z9: 1.6763102e+09 | AA9: 3.39778e+10 | AB9: 2815666.8 | AC9: 0.12064135 | AD9: 9429549.5 | AE9: 0.72456298 | AF9: 19105441 | AG9: 0.66583765 | AH9: 30823906 | AI9: 4.1975352 | AR9: 25.525704 | AS9: -0.10088343 | AT9: -0.35836867 | AU9: -0.6197036 | AV9: -0.68247934 | AW9: -0.62224981 | AX9: 39.782509 | AY9: 67.120551 | AZ9: 80.390687 | BA9: 67.572975 | BB9: 82113
A10: Bancor | B10: BNT | C10: 2017-09-21 | D10: DeFi Exchange | E10: 4.16 | F10: 0.10065099 | G10: -0.36084167 | H10: -0.31758125 | I10: -0.29637248 | J10: 2.810484 | K10: 10.72 | L10: 0.120935 | M10: 4.617146e+08 | N10: 8.0688112e+08 | O10: 8.1003449e+08 | P10: 0.40973323 | Q10: 1.3519008e+09 | R10: -0.071599999 | S10: -0.22604298 | T10: -0.31416148 | U10: -0.20223554 | V10: 0.40424395 | W10: 1.7467389e+09 | X10: 1.9711649e+09 | Y10: 1.6946115e+09 | Z10: 9.6272503e+08 | AA10: 5.2864605e+10 | AB10: 4284116 | AC10: 0.093513258 | AD10: 13469612 | AE10: 0.56504614 | AF10: 29467903 | AG10: 5.473106 | AH10: 32450161 | AI10: 85.727416 | AJ10: 2142058 | AK10: 0.093513258 | AL10: 6734805.8 | AM10: 0.56504614 | AN10: 14733951 | AO10: 5.473106 | AP10: 16225081 | AQ10: 85.727416 | AR10: 5.1076046 | AS10: -0.0092971274 | AT10: -0.2604826 | AU10: -0.50460389 | AV10: -0.69619694 | AW10: -0.85371244 | AX10: 6.9066727 | AY10: 10.310143 | AZ10: 16.812222 | BA10: 34.914826 | BB10: 118727
A11: Barnbridge | B11: BOND | C11: 2020-04-22 | D11: Asset Management DeFi | E11: 24.72 | F11: -0.20992017 | G11: -0.43226547 | H11: -0.40568554 | I11: -0.58194251 | J11: -0.073400313 | K11: 185.69 | L11: 14.22 | M11: 2963860.4 | N11: 65620697 | O11: 247200000 | P11: 0.009134637 | Q11: 83753683 | R11: -0.0030999202 | S11: -0.036732465 | T11: 0.22466328 | U11: -0.66465212 | V11: -0.69396919 | W11: 86947478 | X11: 68389152 | Y11: 2.4975164e+08 | Z11: 2.7367729e+08 | BB11: 17866
A12: Basket DAO | B12: BASK | C12: 2021-03-23 | D12: Asset Management DeFi | Q12: 27543302 | R12: -0.12622276 | S12: -0.30633074 | T12: -0.60572204 | U12: -0.57734542 | V12: -0.57734542 | W12: 39706678 | X12: 69857574 | Y12: 65167405 | Z12: 65167405 | BB12: 2943
A13: Binance Chain | B13: BNB | C13: 2020-09-10 | D13: Blockchain | E13: 278.74 | F13: -0.026440458 | G13: -0.50567384 | H13: -0.47186382 | I13: 0.038555558 | J13: 7.2613755 | K13: 686.31 | L13: 0.0398177 | M13: 7.987128e+09 | N13: 4.2952964e+10 | O13: 4.753455e+10 | P13: 0.1176802 | AA13: 7.7034172e+10 | AC13: -0.33448764 | AD13: 2324172.9 | AE13: -0.29150011 | AF13: 12416243 | AG13: 0.010772639 | AH13: 17036303 | AI13: 0.16155919 | AR13: 1737.0398 | AS13: -0.1222384 | AT13: -0.12094467 | AU13: -0.15752129 | AV13: 0.27553938 | AW13: 0.67863989 | AX13: 1976.0301 | AY13: 2061.8204 | AZ13: 1361.8081 | BA13: 1034.79 | BB13: 639699
A14: Bitcoin | B14: BTC | C14: 2009-01-03 | D14: Blockchain | E14: 35826 | F14: -0.020315104 | G14: -0.23095523 | H14: -0.30015212 | I14: -0.34156522 | J14: 0.87653954 | K14: 64805 | L14: 67.81 | M14: 9.0511677e+10 | N14: 6.7043571e+11 | O14: 752346000000 | P14: 0.12505512 | AA14: 5.2050552e+12 | AB14: 30220814 | AC14: -0.26208377 | AD14: 1.7310822e+08 | AE14: -0.23984877 | AF14: 5.660553e+08 | AG14: -0.010482923 | AH14: 8.9870784e+08 | AI14: 1.646859 | AR14: 369.121 | AS14: 0.11937235 | AT14: 0.1748181 | AU14: 0.081324338 | AV14: -0.15227132 | AW14: -0.26647906 | AX14: 314.19417 | AY14: 341.36011 | AZ14: 435.42351 | BA14: 503.21808 | BB14: 2503911
A15: Centrifuge | B15: CFG | C15: 2020-05-20 | D15: DeFi Lending | AA15: 11280270 | AB15: 26047.301 | AC15: 0.13026086 | AD15: 84219.088 | AE15: 0.7495135 | AF15: 160756.98 | AG15: 3.7402801 | AH15: 190647.54 | AI15: 35.628085 | BB15: 19681
A16: Compound | B16: COMP | C16: 2018-09-27 | D16: DeFi Lending | E16: 383.88 | F16: 0.13965243 | G16: -0.44477675 | H16: -0.35507702 | I16: -0.041724773 | J16: 2.0579599 | K16: 910.54 | L16: 61.32 | M16: 3.0418952e+08 | N16: 1.9834605e+09 | O16: 3838800000 | P16: 0.085001754 | Q16: 7.3957384e+09 | R16: -0.02809021 | S16: -0.1527907 | T16: -0.22740345 | U16: -0.082086949 | V16: 0.36961416 | W16: 8.7295293e+09 | X16: 9.5725749e+09 | Y16: 8.057123e+09 | Z16: 5.39987e+09 | AA16: 7.5880219e+09 | AB16: 9198751.5 | AC16: -0.085824714 | AD16: 38924625 | AE16: -0.24615238 | AF16: 1.2223594e+08 | AG16: 0.23057409 | AH16: 1.7633186e+08 | AI16: 5.2587992 | AJ16: 1025213.4 | AK16: -0.078288206 | AL16: 4347950.9 | AM16: -0.22761007 | AN16: 13927400 | AO16: 0.1648472 | AP16: 20080253 | AQ16: 8.9576079 | AR16: 8.3760619 | AS16: -0.086087225 | AT16: -0.2739373 | AU16: -0.34493364 | AV16: -0.22657038 | AW16: -0.35017073 | AX16: 11.536279 | AY16: 12.786585 | AZ16: 10.829766 | BA16: 12.889635 | BB16: 142846
A17: Cream | B17: CREAM | C17: 2020-09-29 | D17: DeFi Lending | E17: 110.63 | F17: 0.14557652 | G17: -0.15519141 | H17: 0.1930851 | I17: -0.29059727 | J17: 1.4981227 | K17: 374.1 | L17: 9.36 | M17: 6207926.2 | N17: 81876577 | O17: 3.2354263e+08 | P17: 0.01938129 | Q17: 2.1712744e+08 | R17: -0.089128991 | S17: -0.21946463 | T17: -0.30194994 | U17: -0.22200191 | V17: -0.32784272 | W17: 2.7817757e+08 | X17: 3.1104852e+08 | Y17: 2.7908479e+08 | Z17: 3.230307e+08 | AA17: 63627727 | AB17: 336857.98 | AC17: -0.011079838 | AD17: 1204078.2 | AE17: -0.1039801 | AF17: 3876815.1 | AG17: -0.29429221 | AH17: 7076941.3 | AI17: 0.88771235 | AJ17: 34717.716 | AK17: -0.053033041 | AL17: 154994.76 | AM17: -0.13864321 | AN17: 409486.46 | AO17: 0.69589064 | AP17: 727104.26 | AQ17: 1.136299 | AR17: 22.821577 | AS17: 0.059879194 | AT17: -0.032878794 | AU17: -0.023661419 | AV17: -0.0048491903 | AW17: -0.18548287 | AX17: 23.597432 | AY17: 23.374654 | AZ17: 22.932782 | BA17: 28.018535 | BB17: 53376
A18: Curve | B18: CRV | C18: 2020-01-21 | D18: DeFi Exchange | E18: 1.51 | F18: 0.031770371 | G18: -0.52434273 | H18: -0.39502457 | I18: -0.35879181 | J18: 1.2646648 | K18: 54.01 | L18: 0.331577 | M18: 4.144826e+08 | N18: 5.5596233e+08 | O18: 4.9875758e+09 | P18: 0.075896073 | Q18: 7.403184e+09 | R18: -0.0013416949 | S18: -0.085294333 | T18: -0.039889286 | U18: 0.28729369 | V18: 0.84472921 | W18: 8.093515e+09 | X18: 7.7107607e+09 | Y18: 5.7509674e+09 | Z18: 4.0131549e+09 | AA18: 9.7784988e+10 | AB18: 1108240.2 | AC18: 0.032569006 | AD18: 3322010.5 | AE18: 0.25413549 | AF18: 8182842.1 | AG18: 0.75395698 | AH18: 12792839 | AI18: 0.76814518 | AJ18: 554120.1 | AK18: 0.032569006 | AL18: 1661005.3 | AM18: 0.25413549 | AN18: 4091421 | AO18: 0.75395698 | AP18: 6396419.5 | AQ18: 0.76814518 | AR18: 127.51384 | AS18: -0.058746272 | AT18: -0.36886322 | AU18: -0.54555614 | AV18: -0.61857088 | AW18: -0.56263498 | AX18: 202.03836 | AY18: 280.59316 | AZ18: 334.30547 | BA18: 291.55016 | BB18: 122191
A19: Decred | B19: DCR | C19: 2016-02-08 | D19: Blockchain | E19: 105.06 | F19: -0.086891214 | G19: -0.42535605 | H19: -0.43161548 | I19: -0.33300526 | J19: 3.6859578 | K19: 247.35 | L19: 0.43154 | M19: 67253221 | N19: 1.3480509e+09 | P19: 0.03479619 | AA19: 4.2830693e+10 | AB19: 2742.0688 | AC19: -0.01815047 | AD19: 9643.0947 | AE19: -0.15902308 | AF19: 30888.72 | AG19: 0.40227429 | AH19: 41179.697 | AI19: 10.846478 | AR19: 11872.951 | AS19: -0.25034989 | AT19: -0.34369278 | AU19: -0.37993151 | AV19: -0.36611818 | AW19: -0.45687775 | AX19: 18090.539 | AY19: 19147.806 | AZ19: 18730.544 | BA19: 21860.55 | BB19: 45456
A20: dHedge | B20: DHT | C20: 2020-06-17 | D20: Asset Management DeFi | E20: 1.5 | F20: -0.0093012808 | G20: -0.29658214 | H20: -0.46491466 | I20: -0.4342593 | J20: 0.056228075 | K20: 5.52 | L20: 0.362026 | M20: 7231375 | N20: 17667471 | O20: 150000000 | P20: 0.018434169 | Q20: 26336784 | R20: -0.06935999 | S20: -0.1845675 | T20: -0.20776668 | U20: -0.11440502 | V20: -0.10907279 | W20: 32297932 | X20: 33243721 | Y20: 29739084 | Z20: 29561095 | BB20: 12949
A21: DODO | B21: DODO | C21: 2020-09-29 | D21: DeFi Exchange | E21: 1.22 | F21: 0.094096417 | G21: -0.53784796 | H21: -0.56556705 | I21: -0.77121847 | J21: 4.0140378 | K21: 8.38 | L21: 0.150827 | M21: 48548361 | N21: 1.5226167e+08 | O21: 1220000000 | P21: 0.036902408 | Q21: 1.347494e+08 | R21: 0.02564295 | S21: -0.13726752 | T21: -0.087601658 | U21: 0.4956579 | V21: 1.5281012 | W21: 1.5618909e+08 | X21: 1.4768703e+08 | Y21: 90093731 | Z21: 53300635 | AA21: 2.3087494e+10 | AB21: 1041413 | AC21: 0.55997733 | AD21: 1886023.8 | AE21: 1.055678 | AF21: 4027999.4 | AG21: 0.35211803 | AH21: 6549262.2 | AI21: 1.5765489 | AR21: 54.939094 | AS21: -0.073984157 | AT21: -0.51588554 | AU21: -0.77786091 | AV21: -0.80839839 | AW21: -0.71593994 | AX21: 113.48369 | AY21: 247.31845 | AZ21: 286.73607 | BA21: 193.40661 | BB21: 90306
A22: Dogecoin | B22: DOGE | C22: 2013-12-06 | D22: Blockchain | E22: 0.315431 | F22: -0.061356408 | G22: -0.38788757 | H22: 0.26547014 | I22: 4.8923873 | J22: 74.937744 | K22: 0.731578 | L22: 8.69e-05 | M22: 9.267705e+09 | N22: 4.091817e+10 | P22: 0.26582503 | AA22: 1.1002158e+12 | AB22: 321966.94 | AC22: -0.12179911 | AD22: 2227325.1 | AE22: 1.7911317 | AF22: 3146366.2 | AG22: 8.5821264 | AH22: 3403753.9 | AI22: 314.85955 | AR22: 1560.2759 | AS22: -0.19484037 | AT22: -0.25639558 | AU22: -0.49241056 | AV22: -0.56195477 | AW22: -0.63311582 | AX22: 2098.2607 | AY22: 3073.8936 | AZ22: 3561.906 | BA22: 4252.7752 | BB22: 1603241
A23: dYdX | C23: 2018-10-03 | D23: DeFi Exchange | Q23: 1.5434433e+08 | R23: -0.083198466 | S23: -0.30801835 | T23: -0.39910633 | U23: -0.40140094 | V23: -0.15969739 | W23: 2.2304685e+08 | X23: 2.5685797e+08 | Y23: 2.5784258e+08 | Z23: 1.8367708e+08 | AA23: 2.5227557e+10 | AB23: 1809049.7 | AC23: 0.34979632 | AD23: 3875500.4 | AE23: 0.81087253 | AF23: 9093393.3 | AG23: -0.15117601 | AH23: 18751477 | AI23: 3.924737 | AJ23: 1219870.1 | AK23: 0.37846922 | AL23: 2530452.6 | AM23: 0.58765195 | AN23: 6866849.2 | AO23: -0.37255268 | AP23: 15294121 | AQ23: 2.8615752 | BB23: 32802
A24: Ellipsis Finance | B24: EPS | C24: 2021-03-14 | D24: DeFi Exchange | E24: 0.70363 | F24: 0.059463503 | G24: -0.56915356 | H24: -0.58094793 | M24: 8463764.6 | N24: 1.0725418e+08 | O24: 703630000 | P24: 0.016232588 | Q24: 2.0412473e+09 | R24: -0.0081651564 | S24: -0.09341896 | T24: -0.20147812 | U24: -0.138089 | V24: -0.138089 | W24: 2.2515883e+09 | X24: 2.5562822e+09 | Y24: 2.3682808e+09 | Z24: 2.3682808e+09 | BB24: 15795
A25: Enzyme Finance | B25: MLN | C25: 2016-08-01 | D25: Asset Management DeFi | E25: 51.9 | F25: 0.012734457 | G25: -0.43885231 | H25: -0.4717347 | I25: 0.30738822 | J25: 0.70602016 | K25: 258.26 | L25: 1.79 | M25: 7391175.3 | N25: 69500626 | O25: 94688280 | P25: 0.10427735 | Q25: 23791837 | R25: -0.093840758 | S25: -0.15278106 | T25: -0.22861998 | U25: -0.093109905 | V25: -0.093109905 | W25: 28082277 | X25: 30843212 | Y25: 26234532 | Z25: 26234532 | BB25: 24796
A26: Erasure Protocol | B26: NMR | C26: 2015-12-16 | D26: DeFi Prediction Market Other | E26: 39.34 | F26: 0.18173729 | G26: -0.45235277 | H26: -0.34950852 | I26: -0.037039996 | J26: 0.25660629 | K26: 93.15 | L26: 2.06 | M26: 47212451 | N26: 2.2331396e+08 | O26: 4.3274e+08 | P26: 0.069075643 | Q26: 11560534 | R26: -0.090464579 | S26: -0.25677592 | T26: -0.2901238 | U26: -0.23551271 | V26: -0.23551271 | W26: 15554574 | X26: 16285282 | Y26: 15121944 | Z26: 15121944 | BB26: 28786
A27: Ethereum | B27: ETH | C27: 2015-07-30 | D27: Blockchain | E27: 2172.58 | F27: -0.015817057 | G27: -0.39684146 | H27: -0.081062801 | I27: 0.21467154 | J27: 2.6049471 | K27: 4356.99 | L27: 0.432979 | M27: 8.2848852e+10 | N27: 2.5202372e+11 | P27: 0.28724055 | AA27: 7.5320165e+12 | AB27: 2.6457697e+08 | AC27: -0.0067517636 | AD27: 1.0873434e+09 | AE27: 0.38805768 | AF27: 2.499396e+09 | AG27: 0.60209976 | AH27: 3.497501e+09 | AI27: 17.488708 | AR27: 19.685367 | AS27: -0.19897399 | AT27: -0.3085844 | AU27: -0.47130799 | AV27: -0.33635569 | AW27: -0.54994722 | AX27: 28.471106 | AY27: 37.234093 | AZ27: 29.662527 | BA27: 43.74013 | BB27: 1252270
A28: Fei Protocol | B28: TRIBE | C28: 2021-03-21 | D28: Asset Management DeFi Stablecoin | E28: 0.914915 | F28: 0.013622166 | G28: -0.37997363 | H28: -0.31937081 | M28: 44828621 | N28: 3.6858927e+08 | O28: 914915000 | P28: 0.028888205 | Q28: 3.8278131e+08 | R28: -0.018637397 | S28: -0.091446898 | T28: -0.36985942 | U28: -0.49917154 | V28: -0.49917154 | W28: 4.2130868e+08 | X28: 6.0745384e+08 | Y28: 7.6429625e+08 | Z28: 7.6429625e+08 | BB28: 25394
A29: Filecoin | B29: FIL | C29: 2014-07-08 | D29: Blockchain | E29: 65.8 | F29: -0.066142647 | G29: -0.38974478 | H29: -0.52770965 | I29: 0.65839126 | J29: 1.2158756 | K29: 236.84 | L29: 20.06 | M29: 1.7433412e+09 | N29: 4.8366534e+09 | O29: 1.2989946e+11 | P29: 0.45210934 | AC29: -0.56540368 | AD29: 334294.66 | AE29: -0.8295473 | AF29: 2475078.8 | AG29: 1.6905949 | AH29: 2991649.6 | AI29: 1.5396011 | AR29: 33002.491 | AS29: 23.748042 | AT29: 31.426198 | AU29: 45.276292 | AV29: 28.548051 | AW29: 35.642219 | AX29: 1017.7724 | AY29: 713.16196 | AZ29: 1116.9093 | BA29: 900.66846 | BB29: 87927
A30: Futureswap | B30: FST | C30: 2020-04-15 | D30: DeFi Exchange | E30: 5.23 | F30: 0.050863623 | G30: -0.31825789 | H30: -0.31458302 | K30: 16.33 | L30: 4.29 | M30: 440785.28 | N30: 20876441 | O30: 5.23e+08 | P30: 0.0012624956 | Q30: 42525495 | R30: -0.023862986 | S30: -0.15841308 | T30: -0.24816505 | U30: -0.31815152 | V30: -0.31815152 | W30: 50530128 | X30: 56562275 | Y30: 62367954 | Z30: 62367954 | AA30: 1.5167721e+10 | AB30: 608657.84 | AC30: 0.08303341 | AD30: 1739093.5 | AE30: 0.10974289 | AF30: 3843647.5 | AG30: 0.50822131 | AH30: 5493800.4 | AR30: 25.541569 | AS30: -0.071100068 | AT30: -0.24914398 | AU30: -0.35489533 | AV30: -0.58152633 | AW30: -0.58152633 | AX30: 34.016601 | AY30: 39.592907 | AZ30: 61.035069 | BA30: 61.035069 | BB30: 6801
A31: Harvest Finance | B31: FARM | C31: 2020-08-16 | D31: Asset Management DeFi | E31: 69.69 | F31: 0.068024619 | G31: -0.44558315 | H31: -0.65531754 | I31: -0.74115543 | J31: -0.36775518 | K31: 5078.47 | L31: 54.3 | M31: 2319340.1 | N31: 38092621 | O31: 48115370 | P31: 0.035411489 | Q31: 3.3413992e+08 | R31: -0.052334766 | S31: -0.21429678 | T31: -0.34233349 | U31: -0.37951666 | V31: -0.39525181 | W31: 4.2527497e+08 | X31: 5.0806893e+08 | Y31: 5.3851553e+08 | Z31: 5.5252736e+08 | BB31: 48405
A32: Hegic | B32: HEGIC | C32: 2020-02-20 | D32: DeFi Insurance | E32: 0.114512 | F32: 0.18238786 | G32: -0.29988962 | H32: -0.18364552 | I32: -0.68547343 | J32: -0.57246389 | K32: 0.642093 | L32: 0.04329329 | M32: 3463344.4 | N32: 61526811 | O32: 3.4491128e+08 | P32: 0.015201286 | Q32: 41907366 | R32: -0.030116423 | S32: -0.17287003 | T32: -0.29658553 | U32: -0.32192885 | V32: -0.3736552 | W32: 50665998 | X32: 59577059 | Y32: 61803788 | Z32: 66907821 | AA32: 1.2313633e+09 | AB32: 4179611.2 | AC32: 0.66596569 | AD32: 8061176.5 | AE32: 0.8499193 | AF32: 14655855 | AG32: -0.00088297358 | AH32: 31553515 | AI32: 1.1595492 | AJ32: 677040.25 | AK32: 1.2679153 | AL32: 1045815.4 | AM32: 2.2350318 | AN32: 1650874.3 | AO32: 0.93834144 | AP32: 3293562 | AQ32: 0.66674398 | AR32: 3.6339403 | AS32: -0.021851615 | AT32: -0.3844207 | AU32: -0.60920675 | AV32: -0.73647581 | AW32: -0.73904734 | AX32: 5.9032855 | AY32: 9.2988822 | AZ32: 13.789779 | BA32: 13.925669 | BB32: 18183
A33: IDEX | B33: IDEX | C33: 2017-10-14 | D33: DeFi Exchange | E33: 0.04963644 | F33: 0.22492913 | G33: -0.45851685 | H33: -0.60473078 | I33: -0.19263601 | J33: 0.10809581 | K33: 0.409674 | L33: 0.00563813 | M33: 1630644 | N33: 27904488 | O33: 49636440 | P33: 0.045674633 | Q33: 15126439 | R33: -0.11952964 | S33: -0.29237538 | T33: -0.40457575 | U33: -0.39031909 | V33: -0.39031909 | W33: 21376360 | X33: 25404472 | Y33: 24810418 | Z33: 24810418 | AA33: 28863020 | AB33: 1268.9511 | AC33: -0.014330309 | AD33: 7354.1395 | AE33: -0.16673125 | AF33: 30020.034 | AG33: -0.68765368 | AH33: 87587.744 | AI33: -0.71599162 | AJ33: 1268.9511 | AK33: -0.014330309 | AL33: 7354.1395 | AM33: -0.16673125 | AN33: 30020.034 | AO33: -0.68765368 | AP33: 87587.744 | AQ33: -0.71599162 | AR33: 573.24146 | AS33: 0.086090686 | AT33: -0.23414562 | AU33: -0.59178855 | AV33: -0.40770997 | AW33: -0.011188537 | AX33: 748.49929 | AY33: 1404.2758 | AZ33: 967.83912 | BA33: 579.72777 | BB33: 51653
A34: Idle Finance | B34: IDLE | C34: 2019-04-23 | D34: Asset Management DeFi | E34: 7.62 | F34: -0.027948823 | G34: -0.47377656 | H34: -0.30443745 | I34: -0.49374094 | K34: 30.65 | L34: 0.789683 | M34: 237565 | N34: 13278511 | O34: 99060000 | P34: 0.0033205999 | Q34: 1.869269e+08 | R34: 0.056082317 | S34: -0.1375602 | T34: -0.057590079 | U34: 0.23577748 | V34: 0.61334308 | W34: 2.1674197e+08 | X34: 1.9834988e+08 | Y34: 1.5126259e+08 | Z34: 1.1586308e+08 | BB34: 9580
A35: Index Cooperative | B35: INDEX | C35: 2020-10-01 | D35: Asset Management DeFi | E35: 25.34 | F35: -0.012019348 | G35: -0.42255408 | H35: -0.28899483 | I35: 0.018584843 | J35: 2.8002944 | K35: 67.08 | L35: 1.33 | M35: 941017.91 | N35: 43576026 | O35: 253400000 | P35: 0.0029319652 | Q35: 1.9743554e+08 | R35: -0.089251946 | S35: -0.25839893 | T35: -0.21538229 | U35: 0.1373926 | V35: 0.58825213 | W35: 2.6622877e+08 | X35: 2.5163279e+08 | Y35: 1.735861e+08 | Z35: 1.2430995e+08
A36: Indexed Finance | B36: NDX | C36: 2021-04-23 | D36: Asset Management DeFi | E36: 2.75 | F36: 0.049961739 | G36: -0.50355577 | H36: -0.67448509 | I36: -0.71865341 | K36: 27.71 | L36: 1.01 | M36: 267255.91 | N36: 9480919.1 | O36: 27500000 | P36: 0.0034832028 | Q36: 21997039 | R36: -0.092012777 | S36: -0.25267037 | T36: -0.35611673 | U36: -0.34956521 | V36: -0.42337896 | W36: 29434186 | X36: 34163086 | Y36: 33818977 | Z36: 38148173 | BB36: 13338
A37: Instadapp | B37: INST | C37: 2018-10-16 | D37: DeFi Interoperability Other | Q37: 4125589150 | R37: -0.039239089 | S37: -0.11066065 | T37: 0.023244201 | U37: 0.64742543 | V37: 1.9910734 | W37: 4.6389369e+09 | X37: 4.0318715e+09 | Y37: 2.5042646e+09 | Z37: 1.3793005e+09
A38: Integral Protocol | B38: ITGR | C38: 2021-04-21 | D38: DeFi Exchange | Q38: 1.0623063e+08 | R38: -0.05205444 | S38: -0.38503563 | T38: -0.72194251 | U38: -0.74417062 | V38: -0.74417062 | W38: 1.7274274e+08 | X38: 3.8204556e+08 | Y38: 4.1524016e+08 | Z38: 4.1524016e+08 | BB38: 6176
A39: KeeperDAO | B39: ROOK | C39: 2020-07-18 | D39: Asset Management DeFi Other | E39: 189.63 | F39: 0.13782177 | G39: -0.52901631 | H39: -0.40115943 | I39: -0.59406614 | J39: 1.4540222 | K39: 838.98 | L39: 15.61 | M39: 6329241.9 | N39: 1.0715716e+08 | O39: 222682509 | P39: 0.022388573 | Q39: 68882776 | R39: -0.057151386 | S39: -0.23402098 | T39: -0.8186848 | U39: -0.80286384 | V39: -0.73284237 | W39: 89927758 | X39: 3.7990623e+08 | Y39: 3.4941726e+08 | Z39: 2.5783571e+08 | AA39: 5.7241077e+10 | AB39: 0.020925966 | AC39: -0.27641942 | AD39: 5517227.1 | AE39: -0.38249865 | AF39: 24656808 | AG39: -0.6261779 | AH39: 49098764 | AI39: 3.0113399 | AJ39: 0.020925966 | AK39: -0.27641942 | AL39: 5517227.1 | AM39: -0.38249865 | AN39: 24656808 | AO39: -0.6261779 | AP39: 49098764 | AQ39: 3.0113399 | AR39: 3.4279468 | AS39: -0.035143353 | AT39: -0.2430223 | AU39: -0.25160924 | AV39: -0.11941532 | AW39: -0.12764795 | AX39: 4.5284647 | AY39: 4.5804238 | AZ39: 3.8928077 | BA39: 3.9295452 | BB39: 20227
A40: Keep Network | B40: KEEP | C40: 2017-08-10 | D40: DeFi Interoperability | E40: 0.289022 | F40: 0.1393883 | G40: -0.37661515 | H40: -0.38537344 | I40: -0.2125421 | J40: -0.15272487 | K40: 6.1 | L40: 0.177138 | M40: 3289175.7 | N40: 1.2671757e+08 | O40: 289022000 | P40: 0.0053216886 | Q40: 1.883832e+08 | R40: -0.13411246 | S40: -0.3195512 | T40: -0.4502145 | U40: -0.43482732 | V40: -0.28948619 | W40: 2.768514e+08 | X40: 3.4264854e+08 | Y40: 3.3331973e+08 | Z40: 2.6513658e+08 | BB40: 18738
...
